Workbook

Sheet Cursos
E1: Especialidades | L1: Horas semanales | S1: 18 | T1: 30 | W1: =SUM(W3:W140) -> 26435680 | X1: =SUM(X3:X140) -> 0
A2: CODIGO | B2: MATERIA | C2: CURSO | D2: TITULO | E2: Plan Común | F2: ICI | G2: IOC | H2: ICE | I2: ICC | J2: ICA | K2: Cocentración | L2: Clases | M2: Ayudantías | N2: Laboratorios o Talleres | O2: Trabajos | P2: Presentaciones | Q2: Lecturas | R2: Estudio | S2: Horas semanales | T2: SCT-Chile | U2: Requisitos | V2: Habilidades Transversales | W2: Comienzo | X2: Secciones Sem 10 | Y2: Secciones Sem 20 | Z2: Homologación Plan de Estudios 2016 Sólo cambio de malla | AA2: Homologación Plan de Estudios 2011 Sólo cambio de malla | AB2: Cursos similares del Plan de Estudios 2011 (Lista Cruzada) | AC2: CODIGOS BANNER 2010 | AD2: COINCIDENCIA
A3: ICI2010 | B3: ICI | C3: 2010 | D3: Administración de los Riesgos Financieros | F3: 10f | L3: 3 | O3: 2 | P3: 1 | Q3: 1 | R3: 3 | S3: =SUM(L3:R3) -> 10 | T3: =ROUND(S3*S$1/T$1,0) -> 6 | U3: Licenciatura | W3: 201920 | Y3: ✔ | AB3: Administración de los Riesgos Financieros | AC3: 6 | AD3: SI
A4: IOC5206 | B4: IOC | C4: 5206 | D4: Administración y Control de Proyectos | G4: 10i | L4: 3 | O4: 4 | R4: 3 | S4: 10 | T4: 6 | U4: Cost Engineering | V4: Ob | W4: 201920 | Y4: ✔ | AB4: Análisis Conceptual de Proyectos | AC4: 6 | AD4: SI
A5: ICA5120 | B5: ICA | C5: 5120 | D5: Air Quality and Environmental Pollution | J5: 9 | L5: 3 | M5: 0 | N5: 1 | P5: 1 | R5: 5 | S5: =SUM(L5:R5) -> 10 | T5: =ROUND(S5*S$1/T$1,0) -> 6 | U5: Diseño y Optimización de Procesos Industriales | V5: Ic(Oa) | W5: 201910 | X5: ✔ | Z5: Air Quality and Environmental Pollution (ICA 5102) | AB5: NA | AC5: 6 | AD5: SI
A6: ING1100 | B6: ING | C6: 1100 | D6: Álgebra e Introducción al Cálculo | E6: 1 | F6: 1 | G6: 1 | H6: 1 | I6: 1 | J6: 1 | L6: 8 | M6: 4 | R6: 5 | S6: =SUM(L6:R6) -> 17 | T6: =ROUND(S6*S$1/T$1,0) -> 10 | W6: 201610 | X6: ✔ | Y6: ✔ | AA6: Álgebra (7) y Geometría e Introducción al Cálculo (7) | AB6: Álgebra y Geometría e Introducción al Cálculo | AC6: no disponible | AD6: NO
A7: ING1201 | B7: ING | C7: 1201 | D7: Álgebra Lineal | E7: 2 | F7: 2 | G7: 2 | H7: 2 | I7: 2 | J7: 2 | L7: 4 | M7: 2 | N7: 1 | R7: 3 | S7: =SUM(L7:R7) -> 10 | T7: =ROUND(S7*S$1/T$1,0) -> 6 | U7: Bases para el Estudio de Ingeniería, Álgebra e Introducción al Cálculo, Programación (p) | W7: 201620 | X7: ✔ | Y7: ✔ | AA7: Álgebra Lineal (6) | AB7: Álgebra Lineal | AC7: 6 | AD7: SI
A8: ICC4101 | B8: ICC | C8: 4101 | D8: Algorithms and Competitive Programming | I8: 7 | K8: 7 | N8: 4 | Q8: 2 | R8: 4 | S8: 10 | T8: 6 | U8: Estructuras de Datos y Algoritmos | V8: Ic | W8: 201810 | X8: ✔ | AB8: Diseño y Análisis de Algoritmos | AC8: 6 | AD8: SI
A9: ICC5140 | B9: ICC | C9: 5140 | D9: Almacenamiento y Procesamiento Masivo de Datos | I9: 9 | L9: 2 | O9: 4 | P9: 1 | Q9: 1 | R9: 2 | S9: 10 | T9: 6 | U9: Proyecto de Desarrollo de Software | V9: Ec | W9: 201910 | X9: ✔ | AB9: Electivo Computación | AC9: 6 | AD9: SI
A10: ICE3101 | B10: ICE | C10: 3101 | D10: Análisis de Circuitos | H10: 5 | K10: 5 | L10: 3 | M10: 2 | N10: 1 | R10: 4 | S10: =SUM(L10:R10) -> 10 | T10: =ROUND(S10*S$1/T$1,0) -> 6 | U10: Ecuaciones Diferenciales, Electricidad y Magnetismo | W10: 201710 | X10: ✔ | AA10: Análisis de Circuitos (6) | AB10: Análisis de Circuitos | AC10: 6 | AD10: SI
A11: ICI1010 | B11: ICI | C11: 1010 | D11: Análisis de Estados Financieros | F11: 9f | L11: 3 | O11: 2 | P11: 1 | Q11: 1 | R11: 3 | S11: =SUM(L11:R11) -> 10 | T11: =ROUND(S11*S$1/T$1,0) -> 6 | U11: Licenciatura | V11: Ib,Oa | W11: 201910 | X11: ✔ | AB11: Análisis de Estados Financieros | AC11: 6 | AD11: SI
A12: IOC3201 | B12: IOC | C12: 3201 | D12: Análisis Estructural | G12: 6 | L12: 3 | M12: 2 | Q12: 1 | R12: 4 | S12: 10 | T12: 6 | U12: Mecánica de Materiales | W12: 201720 | Y12: ✔ | AB12: Análisis Estructural | AC12: 6 | AD12: SI
A13: ING1106 | B13: ING | C13: 1106 | D13: Antropología Filosófica | E13: 1 | F13: 1 | G13: 1 | H13: 1 | I13: 1 | J13: 1 | L13: 2 | Q13: 2 | R13: 1 | S13: =SUM(L13:R13) -> 5 | T13: =ROUND(S13*S$1/T$1,0) -> 3 | W13: 201610 | X13: ✔ | Y13: ✔ | AA13: Antropología Filosófica (3) | AB13: Antropología Filosófica | AC13: no disponible | AD13: NO
A14: ICC4203 | B14: ICC | C14: 4203 | D14: Aplicaciones Móviles | I14: 8 | L14: 2 | N14: 2 | O14: 2 | Q14: 1 | R14: 3 | S14: 10 | T14: 6 | U14: Web Technologies | V14: Ia | W14: 201810 | Y14: ✔ | AB14: Aplicaciones móviles | AC14: 6 | AD14: SI
A15: ICC3202 | B15: ICC | C15: 3202 | D15: Arquitectura de Computadores | I15: 6 | K15: 6* | L15: 3 | O15: 2 | R15: 5 | S15: 10 | T15: 6 | U15: Electricidad y Magnetismo | W15: 201720 | Y15: ✔ | AB15: Arquitectura de Computadores | AC15: 6 | AD15: SI
A16: ICE5204 | B16: ICE | C16: 5204 | D16: Artificial Intelligence (nueva malla electrica) | H16: 10 | I16: 8 | L16: 2 | M16: 2 | O16: 4 | R16: 2 | S16: =SUM(L16:R16) -> 10 | T16: =ROUND(S16*S$1/T$1,0) -> 6 | U16: (Probabilidad y Estadística, Señales y Sistemas) o (Probabilidades y Estadísticas y Programación de bajo nivel) | V16: Ic(Oa) | W16: 201820 | Y16: ✔ | AB16: Inteligencia Artificial | AC16: 6 | AD16: SI
A17: ICC3103 | B17: ICC | C17: 3103 | D17: Autómatas y Computabilidad | I17: 5 | L17: 3 | R17: 7 | S17: 10 | T17: 6 | U17: Programación, Cálculo I | V17: Ib | W17: 201710 | X17: ✔ | AB17: Teoría de Autómatas y Lenguajes formales | AC17: 6 | AD17: SI
A18: ICA4130 | B18: ICA | C18: 4130 | D18: Balances de Materia y Energía | J18: 7 | L18: 3 | M18: 2 | Q18: 1 | R18: 4 | S18: =SUM(L18:R18) -> 10 | T18: =ROUND(S18*S$1/T$1,0) -> 6 | U18: Métodos Numéricos, Transferencia de Calor | V18: Ia | W18: 201710 | X18: ✔ | Z18: Balances de Materia y Energía (ICA 3101) | AB18: NA | AC18: 6 | AD18: SI
A19: ICC3204 | B19: ICC | C19: 3204 | D19: Bases de Datos | F19: 5 | I19: 6 | K19: 6* | L19: 3 | O19: 3 | R19: 4 | S19: 10 | T19: 6 | U19: Programación | W19: 201710 | X19: ✔ | Y19: ✔ | AA19: Bases de Datos Aplicadas (5) | AB19: Bases de Datos Aplicadas (5) | AC19: 6 | AD19: SI
A20: ING1400 | B20: ING | C20: 1400 | D20: Bases para el Estudio de Ingeniería | E20: 1 | F20: 1 | G20: 1 | H20: 1 | I20: 1 | J20: 1 | L20: 10 | R20: 10 | S20: =SUM(L20:R20) -> 20 | T20: =ROUND(S20/#REF!,0) -> #REF! | W20: 201610 | X20: ✔ | AA20: Álgebra (7) o Geometría e Introducción al Cálculo (7) | AB20: NA | AC20: no disponible | AD20: NO
A21: ING1204 | B21: ING | C21: 1204 | D21: Biología de los Microorganismos | E21: 2 | F21: 2 | G21: 2 | H21: 2 | I21: 2 | J21: 2 | L21: 3 | N21: 1 | O21: 1 | P21: 1 | Q21: 1 | R21: 2 | S21: =SUM(L21:R21) -> 9 | T21: =ROUND(S21*S$1/T$1,0) -> 5 | U21: Bases para el Estudio de Ingeniería (p) | V21: Ea | W21: 201620 | X21: ✔ | Y21: ✔ | AB21: NA | AC21: 0 | AD21: NO
A22: ING1202 | B22: ING | C22: 1202 | D22: Cálculo I | E22: 2 | F22: 2 | G22: 2 | H22: 2 | I22: 2 | J22: 2 | L22: 4 | M22: 2 | R22: 4 | S22: =SUM(L22:R22) -> 10 | T22: =ROUND(S22*S$1/T$1,0) -> 6 | U22: Bases para el Estudio de Ingeniería, Álgebra e Introducción al Cálculo | W22: 201620 | X22: ✔ | Y22: ✔ | AA22: Cálculo I (6) | AB22: Cálculo I (6) | AC22: 6 | AD22: SI
A23: ING2102 | B23: ING | C23: 2102 | D23: Cálculo II | E23: 3 | F23: 3 | G23: 3 | H23: 3 | I23: 3 | J23: 3 | L23: 4 | M23: 2 | R23: 4 | S23: =SUM(L23:R23) -> 10 | T23: =ROUND(S23*S$1/T$1,0) -> 6 | U23: Programación, Cálculo I | W23: 201710 | X23: ✔ | Y23: ✔ | AA23: Cálculo II (6) | AB23: Cálculo II (6) | AC23: 6 | AD23: SI
A24: ICA4110 | B24: ICA | C24: 4110 | D24: Cinética y Diseño de Reactores Químicos | J24: 8 | L24: 3 | M24: 2 | Q24: 2 | R24: 3 | S24: =SUM(L24:R24) -> 10 | T24: =ROUND(S24*S$1/T$1,0) -> 6 | U24: Balances de Materia y Energía, Máquinas de Transformación Física y Química | V24: Ib | W24: 201720 | Y24: ✔ | Z24: Cinética y Diseño de Reactores Químicos (ICA4101) | AB24: NA | AC24: 6 | AD24: SI
A25: ICE4204 | B25: ICE | C25: 4204 | D25: Comunicaciones Digitales | H25: 8 | L25: 3 | N25: 2 | R25: 5 | S25: =SUM(L25:R25) -> 10 | T25: =ROUND(S25*S$1/T$1,0) -> 6 | U25: Introducción a las Comunicaciones | W25: 201820 | Y25: ✔ | AB25: Comunicaciones Modernas | AC25: 6 | AD25: SI
A26: ICI3203 | B26: ICI | C26: 3203 | D26: Contabilidad y Control de Gestión | F26: 6 | L26: 3 | O26: 2 | P26: 1 | Q26: 1 | R26: 3 | S26: =SUM(L26:R26) -> 10 | T26: =ROUND(S26*S$1/T$1,0) -> 6 | U26: Fundamentos de Economía | W26: 201720 | X26: ✔ | Y26: ✔ | AB26: Contabilidad General y de costos | AC26: 6 | AD26: SI
A27: ICE4202 | B27: ICE | C27: 4202 | D27: Control Automático | H27: 8 | L27: 3 | N27: 2 | O27: 2 | R27: 3 | S27: =SUM(L27:R27) -> 10 | T27: =ROUND(S27*S$1/T$1,0) -> 6 | U27: Señales y Sistemas, Mecánica y Ondas | V27: Ec | W27: 201820 | Y27: ✔ | AB27: Control Automático | AC27: 6 | AD27: SI
A28: ICE4104 | B28: ICE | C28: 4104 | D28: Conversión de Energía | H28: 7 | L28: 3 | N28: 2 | O28: 2 | R28: 3 | S28: =SUM(L28:R28) -> 10 | T28: =ROUND(S28*S$1/T$1,0) -> 6 | U28: Análisis de Circuitos, Termodinámica (concurrente) | V28: Ec | W28: 201810 | X28: ✔ | AB28: Conversión de Energía | AC28: 6 | AD28: SI
A29: IOC5106 | B29: IOC | C29: 5106 | D29: Cost Engineering | G29: 9i | L29: 3 | O29: 4 | R29: 3 | S29: 10 | T29: 6 | U29: 228 SCT Aprobados en total | V29: Ic | W29: 201910 | X29: ✔ | AB29: Electivo Obras | AC29: 6 | AD29: SI
A30: ICC5130 | B30: ICC | C30: 5130 | D30: Diseño de Software Verificable | I30: 9 | L30: 3 | O30: 3 | Q30: 2 | R30: 2 | S30: 10 | T30: 6 | U30: Proyecto de Desarrollo de Software | W30: 201910 | X30: ✔ | AB30: Calidad y Verificación de Software | AC30: 6 | AD30: SI
A31: IOC5120 | B31: IOC | C31: 5120 | D31: Diseño en Acero | G31: 9 | L31: 3 | M31: 2 | O31: 1 | R31: 4 | S31: 10 | T31: 6 | U31: 228 SCT Aprobados en total | W31: 201910 | X31: ✔ | AB31: Introducción al Diseño en madera y acero | AC31: 6 | AD31: SI
A32: IOC5204 | B32: IOC | C32: 5204 | D32: Diseño Sismorresistente | G32: 10e | L32: 3 | M32: 2 | O32: 1 | P32: 1 | R32: 3 | S32: 10 | T32: 6 | U32: Hormigón Armado , Dynamics of Structures | W32: 201920 | Y32: ✔ | AB32: Diseño Sismorresistente | AC32: 6 | AD32: SI
A33: ICI4201 | B33: ICI | C33: 4201 | D33: Diseño y Evaluación de Proyectos Industriales | F33: 8 | L33: 3 | O33: 5 | P33: 3 | Q33: 1 | R33: 3 | S33: =SUM(L33:R33) -> 15 | T33: =ROUND(S33*S$1/T$1,0) -> 9 | U33: Gestión de Operaciones, Finanzas, Modelos Estocásticos | V33: Ec | W33: 201820 | X33: ✔ | Y33: ✔ | AB33: Podría ser Evaluación de Proyectos para ICI | AC33: 9 | AD33: SI
A34: ICA4210 | B34: ICA | C34: 4210 | D34: Diseño y Optimización de Procesos Industriales | J34: 8 | L34: 3 | M34: 2 | N34: 0 | O34: 6 | P34: 1 | R34: 3 | S34: =SUM(L34:R34) -> 15 | T34: =ROUND(S34*S$1/T$1,0) -> 9 | U34: Balances de Materia y Energía, Máquinas de Transformación Física y Química, Ecología, Medio Ambiente y Energía | V34: Ec | W34: 201820 | Y34: ✔ | Z34: Diseño y Optimización de Procesos Industriales (ICA 4201) | AB34: NA | AC34: 9 | AD34: SI
A35: IOC5100 | B35: IOC | C35: 5100 | D35: Dynamics of Structures | G35: 9 | L35: 3 | M35: 2 | O35: 1 | P35: 1 | R35: 3 | S35: 10 | T35: 6 | U35: 228 SCT Aprobados en total | V35: Ic(Oa) | W35: 201910 | X35: ✔ | AB35: Dinámica de Estructuras | AC35: 6 | AD35: SI
A36: ICA3130 | B36: ICA | C36: 3130 | D36: Ecología, Medio Ambiente y Energía | J36: 6 | L36: 3 | N36: 1 | O36: 2 | P36: 1 | Q36: 1 | R36: 2 | S36: =SUM(L36:R36) -> 10 | T36: =ROUND(S36*S$1/T$1,0) -> 6 | U36: Microbiología Industrial y Ambiental | V36: Ec | W36: 201710 | Y36: ✔ | Z36: Ecología, Medio Ambiente y Energía (ICA3103) | AB36: NA | AC36: 6 | AD36: SI
A37: ICI5104 | B37: ICI | C37: 5104 | D37: Econometría | F37: 10 | L37: 3 | M37: 2 | O37: 1 | Q37: 1 | R37: 3 | S37: =SUM(L37:R37) -> 10 | T37: =ROUND(S37*S$1/T$1,0) -> 6 | U37: Licenciatura | W37: 201920 | X37: ✔ | Y37: ✔ | AB37: Econometría y Demanda por Transporte | AC37: 6 | AD37: SI
A38: ICA5220 | B38: ICA | C38: 5220 | D38: Economía Ambiental y de los Recursos Naturales | J38: 10 | L38: 3 | M38: 2 | O38: 1 | Q38: 1 | R38: 3 | S38: =SUM(L38:R38) -> 10 | T38: =ROUND(S38*S$1/T$1,0) -> 6 | U38: Evaluación de Proyectos de Ingeniería Ambiental | W38: 201920 | Y38: ✔ | Z38: Economía Ambiental y de los Recursos Naturales (ICA 5202) | AB38: NA | AC38: 6 | AD38: SI
A39: ING2101 | B39: ING | C39: 2101 | D39: Ecuaciones Diferenciales | E39: 3 | F39: 3 | G39: 3 | H39: 3 | I39: 3 | J39: 3 | L39: 3 | M39: 2 | N39: 1 | R39: 4 | S39: =SUM(L39:R39) -> 10 | T39: =ROUND(S39*S$1/T$1,0) -> 6 | U39: Programación, Álgebra Lineal, Cálculo I | W39: 201710 | X39: ✔ | Y39: ✔ | AA39: Ecuaciones Diferenciales (6) | AB39: Ecuaciones Diferenciales (6) | AC39: 6 | AD39: SI
A40: ING2202 | B40: ING | C40: 2202 | D40: Electricidad y Magnetismo | E40: 4 | F40: 4 | G40: 4 | H40: 4 | I40: 4 | J40: 4 | L40: 4 | M40: 2 | N40: 1 | R40: 3 | S40: =SUM(L40:R40) -> 10 | T40: =ROUND(S40*S$1/T$1,0) -> 6 | U40: Cálculo II, Mecánica y Ondas | V40: Eb | W40: 201710 | X40: ✔ | Y40: ✔ | AA40: Electromagnetismo (6) | AB40: Electromagnetismo (6) | AC40: 6 | AD40: SI
...

Sheet Malla base
B2: Año 1 | J2: Año 2 | R2: Año 3 | Z2: Año 4 | AI2: Año 5 | AQ2: Año 6
B3: 1 | F3: 2 | J3: 1 | N3: 2 | R3: 1 | V3: 2 | Z3: 1 | AD3: 2 | AI3: 1 | AM3: 2 | AQ3: 1
A4: Curso 1 | B4: 1 | C4: 10 | D4: - | E4: - | F4: 8 | G4: 6 | H4: - | I4: 1,4,3 | J4: 14 | K4: 6 | L4: - | M4: 3,8,9 | N4: 20 | O4: 6 | P4: - | Q4: 15 | R4: 26 | S4: 6 | V4: 32 | W4: 6 | Z4: 38 | AA4: 6 | AD4: 43 | AE4: 9 | AI4: 48 | AJ4: 6 | AM4: 53 | AN4: 6 | AQ4: 60 | AR4: 6
B5: Álgebra e Introducción al Cálculo | F5: Álgebra Lineal | J5: Ecuaciones Diferenciales | N5: Probabilidades y Estadística | R5: Licenciatura Especialidad | V5: Licenciatura Especialidad | Z5: Licenciatura Especialidad | AD5: Proyecto Licenciatura | AI5: Especialidad | AM5: Especialidad | AQ5: Electivo Especialidad
A6: Curso 2 | B6: 2 | C6: 5 | D6: Ea | E6: - | F6: 9 | G6: 6 | H6: - | I6: 1,4 | J6: 15 | K6: 6 | L6: - | M6: 3.9 | N6: 21 | O6: 6 | P6: Eb | Q6: 15,16 | R6: 27 | S6: 6 | V6: 33 | W6: 6 | Z6: 39 | AA6: 6 | AD6: 44 | AE6: 6 | AI6: 49 | AJ6: 6 | AM6: 54 | AN6: 6 | AQ6: 61 | AR6: 6
B7: Fundamentos de Química | F7: Cálculo I | J7: Cálculo II | N7: Electricidad y Magnetismo | R7: Licenciatura Especialidad | V7: Licenciatura Especialidad | Z7: Licenciatura Especialidad | AD7: Licenciatura Especialidad | AI7: Especialidad | AM7: Especialidad | AQ7: Electivo Especialidad
A8: Curso 3 | B8: 3 | C8: 5 | D8: - | E8: - | F8: 10 | G8: 6 | H8: - | I8: 1 | J8: 16 | K8: 6 | L8: Eb | M8: 10 | N8: 22 | O8: 5 | P8: Eb | Q8: 2,15,16 | R8: 28 | S8: 6 | V8: 34 | W8: 6 | Z8: 40 | AA8: 6 | AD8: 45 | AE8: 6 | AI8: 50 | AJ8: 6 | AM8: 55 | AN8: 4 | AO8: Ec,Ob | AP8: 276 cr | AQ8: 62 | AR8: 18 | AS8: Ec, Ob | AT8: 55
B9: Programación | F9: Introducción a la Mecánica | J9: Mecánica y Ondas | N9: Termodinámica | R9: Licenciatura Especialidad | V9: Licenciatura Especialidad | Z9: Licenciatura Especialidad | AD9: Licenciatura Especialidad | AI9: Especialidad | AM9: Proyecto de Título 1 | AQ9: Proyecto de Título 2
A10: Curso 4 | B10: 4 | C10: 1 | D10: - | E10: - | F10: 11 | G10: 5 | H10: Ea | I10: 4 | J10: 17 | K10: 5 | L10: Ia | M10: 1 | N10: 23 | O10: 6 | P10: - | Q10: 9,16 | R10: 29 | S10: 6 | V10: 35 | W10: 6 | Z10: 41 | AA10: 6 | AD10: 46 | AE10: 6 | AI10: 51 | AJ10: 6 | AM10: 56 | AN10: 6
B11: Bases para el Estudio de Ingeniería | F11: Biología de los Microorganismos | J11: Fundamentos de Economía | N11: Estática | R11: Concentración Tecnológica | V11: Licenciatura Especialidad | Z11: Concentración Tecnológica | AD11: Licenciatura Especialidad | AI11: Mención/Electivo Especialidad | AM11: Mención/Electivo Especialidad
A12: Curso 5 | B12: 5 | C12: 3 | E12: - | N12: 24 | O12: 3 | Q12: 7 | V12: 36 | W12: 6 | Z12: 42 | AA12: 6 | AB12: Ib(Ea) | AC12: 150 cr | AI12: 52 | AJ12: 6 | AM12: 57 | AN12: 6
B13: Taller de Proyectos de Ingeniería | N13: Ética | V13: Concentración Tecnológica | Z13: Pensamiento de Diseño Aplicado a Ingeniería | AI13: Mención/Electivo Especialidad | AM13: Mención/Electivo Especialidad
A14: Curso 6 | B14: 6 | C14: 3 | D14: - | E14: - | F14: 12 | G14: 3 | H14: - | I14: 6 | J14: 18 | K14: 3 | L14: - | M14: 12 | N14: 25 | O14: 4 | P14: - | Q14: - | R14: 30 | S14: 3 | T14: - | U14: 24 | AD14: 47 | AE14: 3 | AF14: - | AG14: - | AM14: 58 | AN14: 2 | AO14: Ec,Ia | AP14: 270cr
B15: Teología I | F15: Teología II | J15: Teología III | N15: Minor | R15: Filosofía de las Ciencias | AD15: Optativo Arte y Literatura/Historia y Pensamiento Contemporáneo | AM15: Seminario Ética Profesional
A16: Curso 7 | B16: 7 | C16: 3 | D16: - | E16: - | F16: 13 | G16: 3 | H16: - | I16: - | J16: 19 | K16: 4 | L16: - | M16: - | R16: 31 | S16: 4 | T16: - | U16: -
B17: Antropología Filosófica | F17: Optativo Arte y Literatura/Historia y Pensamiento Contemporáneo | J17: Minor | R17: Minor
X18: 37 | Y18: 12 | Z18: Ic(Ea) | AA18: 170 cr | AO18: 59 | AP18: 12 | AQ18: Ic(Eb, Ob) | AR18: 282 cr
E19: * | F19: APR | X19: Pre-Professional Practice | AO19: Professional Practice
E20: Inglés ALTE 3
B22: # | C22: SCT | D22: HT | E22: Req.
B23: Nombre Curso

Sheet ICI Malla
B2: Año 1 | J2: Año 2 | R2: Año 3 | Z2: Año 4 | AI2: Año 5 | AQ2: Año 6
B3: 1 | F3: 2 | J3: 1 | N3: 2 | R3: 1 | V3: 2 | Z3: 1 | AD3: 2 | AI3: 1 | AM3: 2 | AQ3: 1
A4: Curso 1 | B4: 1 | C4: 10 | D4: ='Malla base'!D4 -> - | E4: - | F4: 8 | G4: 6 | H4: - | I4: 1,4,3 | J4: 14 | K4: 6 | L4: - | M4: 3,8,9 | N4: 20 | O4: 6 | P4: - | Q4: 15 | R4: 26 | S4: 6 | U4: 15 | V4: 32 | W4: 6 | Y4: 20,26 | Z4: 38 | AA4: 6 | AB4: Ib | AC4: 33 | AD4: 43 | AE4: 9 | AF4: Ec | AG4: 32,38,40 | AI4: 48 | AJ4: 6 | AL4: Lic | AM4: 53 | AN4: 6 | AO4: Ib | AP4: Lic | AQ4: 60 | AR4: 6
B5: Álgebra e Introducción al Cálculo | F5: Álgebra Lineal | J5: Ecuaciones Diferenciales | N5: Probabilidades y Estadística | R5: Optimización | V5: Modelos Estocásticos | Z5: Gestión de Operaciones | AD5: Diseño y Evaluación de Proyectos Industriales | AI5: Organización Industrial | AM5: Gestión Estratégica | AQ5: Electivo Especialidad
A6: Curso 2 | B6: 2 | C6: 5 | D6: ='Malla base'!D6 -> Ea | E6: - | F6: 9 | G6: 6 | H6: - | I6: 1,4 | J6: 15 | K6: 6 | L6: - | M6: 3,9 | N6: 21 | O6: 6 | P6: ='Malla base'!P6 -> Eb | Q6: 15,16 | R6: 27 | S6: 6 | T6: Ec | U6: 20 | V6: 33 | W6: 6 | Y6: 20,26 | Z6: 39 | AA6: 6 | AB6: Ic(Ea) | AC6: 27 | AD6: 44 | AE6: 6 | AG6: 27,32 | AI6: 49 | AJ6: 6 | AK6: Ec | AL6: Lic | AM6: 54 | AN6: 6 | AP6: Lic | AQ6: 61 | AR6: 6
B7: Fundamentos de Química | F7: Cálculo I | J7: Cálculo II | N7: Electricidad y Magnetismo | R7: Métodos Estadísticos para la Gestión | V7: Programación Matemática | Z7: Marketing | AD7: Simulación | AI7: Instrumentos Financieros | AM7: Econometría | AQ7: Electivo Mención
A8: Curso 3 | B8: 3 | C8: 5 | D8: - | E8: - | F8: 10 | G8: 6 | H8: ='Malla base'!H8 -> - | I8: 1 | J8: 16 | K8: 6 | L8: ='Malla base'!L8 -> Eb | M8: 10 | N8: 22 | O8: 5 | P8: ='Malla base'!P8 -> Eb | Q8: 2,15,16 | R8: 28 | S8: 6 | U8: 3 | V8: 34 | W8: 6 | Y8: 17 | Z8: 40 | AA8: 6 | AC8: 17,34 | AD8: 45 | AE8: 6 | AG8: 17 | AI8: 50 | AJ8: 6 | AK8: Ic(Oa) | AL8: Lic | AM8: 55 | AN8: 4 | AP8: 276 cr | AQ8: 62 | AR8: 18 | AT8: 55
B9: Programación | F9: Introducción a la Mecánica | J9: Mecánica y Ondas | N9: Termodinámica | R9: Bases de Datos | V9: Contabilidad y Control de Gestión | Z9: Finanzas | AD9: Macroeconomía | AI9: Logistics | AM9: Proyecto de Título 1 | AQ9: Proyecto de Título 2
A10: Curso 4 | B10: 4 | C10: 1 | D10: - | E10: - | F10: 11 | G10: 5 | H10: ='Malla base'!H10 -> Ea | I10: 4 | J10: 17 | K10: 5 | L10: ='Malla base'!L10 -> Ia | M10: 1 | N10: 23 | O10: 6 | P10: - | Q10: 9,16 | R10: 29 | S10: 6 | V10: 35 | W10: 6 | X10: Ia | Y10: 17 | Z10: 41 | AA10: 6 | AD10: 46 | AE10: 6 | AG10: 34 | AI10: 51 | AJ10: 6 | AM10: 56 | AN10: 6
B11: Bases para el Estudio de Ingeniería | F11: Biología de los Microorganismos | J11: Fundamentos de Economía | N11: Estática | R11: Concentración Tecnológica | V11: Microeconomía | Z11: Concentración Tecnológica | AD11: Gestión de Personas y Desarrollo Organizacional | AI11: Mención | AM11: Mención
A12: Curso 5 | B12: 5 | C12: 3 | E12: - | N12: 24 | O12: 3 | Q12: 7 | V12: 36 | W12: 6 | Z12: 42 | AA12: 6 | AB12: Ib(Ea) | AC12: 150 cr | AI12: 52 | AJ12: 6 | AM12: 57 | AN12: 6
B13: Taller de Proyectos de Ingeniería | N13: Ética | V13: Concentración Tecnológica | Z13: Pensamiento de Diseño Aplicado a Ingeniería | AI13: Electivo Especialidad | AM13: Mención
A14: Curso 6 | B14: 6 | C14: 3 | D14: - | E14: - | F14: 12 | G14: 3 | H14: - | I14: 6 | J14: 18 | K14: 3 | L14: - | M14: 12 | N14: 25 | O14: 4 | P14: - | Q14: - | R14: 30 | S14: 3 | T14: - | U14: 24 | AD14: 47 | AE14: 3 | AF14: - | AG14: - | AM14: 58 | AN14: 2 | AO14: Ec | AP14: 270 cr
B15: Teología I | F15: Teología II | J15: Teología III | N15: Minor | R15: Filosofía de las Ciencias | AD15: Optativo Arte y Literatura/Historia y Pensamiento Contemporáneo | AM15: Seminario Ética Profesional
A16: Curso 7 | B16: 7 | C16: 3 | D16: - | E16: - | F16: 13 | G16: 3 | H16: - | I16: - | J16: 19 | K16: 4 | L16: - | M16: - | R16: 31 | S16: 4 | T16: - | U16: -
B17: Antropología Filosófica | F17: Optativo Arte y Literatura/Historia y Pensamiento Contemporáneo | J17: Minor | R17: Minor
X18: 37 | Y18: 12 | Z18: ='Malla base'!Z18 -> Ic(Ea) | AA18: 170 cr | AO18: 59 | AP18: 12 | AQ18: ='Malla base'!AQ18 -> Ic(Eb, Ob) | AR18: 282 cr
E19: * | F19: APR | X19: Pre-Professional Practice | AO19: Professional Practice
E20: Inglés ALTE 3
B22: # | C22: SCT | D22: HT | E22: Req.
B23: Nombre Curso
B24: Año 1 | J24: Año 2 | R24: Año 3 | Z24: Año 4 | AI24: Año 5 | AQ24: Año 6
B25: =C4+C6+C8+C10+C12+C14+C16+G4+G6+G8+G10+G14+G16 -> 59 | J25: =K4+K6+K8+K10+K14+K16+O4+O6+O8+O10+O14+O12 -> 60 | R25: =S4+S6+S8+S10+S14+S16+W4+W6+W8+W10+W12+Y18 -> 73 | Z25: =AA4+AA6+AA8+AA10+AA12+AA14+AE4+AE6+AE8+AE10+AE14 -> 60 | AI25: =AJ4+AJ6+AJ8+AJ10+AJ12+AN4+AN6+AN8+AN10+AN12+AN14+AP18 -> 72 | AQ25: =AR4+AR6+AR8 -> 30

Sheet ICI Lic
A2: Sem | B2: 1 | C2: 10 | D2: - | E2: 2 | F2: 5 | G2: - | H2: 3 | I2: 5 | J2: - | K2: 4 | L2: 1 | M2: - | N2: 5 | O2: 3 | P2: - | R2: 6 | S2: 3 | T2: - | U2: 7 | V2: 3 | W2: -
A3: 1 | B3: Álgebra e Introducción al Cálculo | E3: Fundamentos de Química | H3: Programación | K3: Bases para el Estudio de Ingeniería | N3: Taller de Proyectos de Ingeniería | R3: Teología I | U3: Antropología Filosófica | Z3: * | AA3: APR
Z4: Inglés ALTE 3
B5: 8 | C5: 6 | D5: 1,4,3 | E5: 9 | F5: 6 | G5: 1,4 | H5: 10 | I5: 6 | J5: 1 | K5: 11 | L5: 5 | M5: 4 | R5: 12 | S5: 3 | T5: 6 | U5: 13 | V5: 3 | W5: -
A6: 2 | B6: Álgebra Lineal | E6: Cálculo I | H6: Introducción a la Mecánica | K6: Biología de los Microorganismos | R6: Teología II | U6: Opt. Arte y Lit./Hist. y Pens. Cont.
B8: 14 | C8: 6 | D8: 3,8,9 | E8: 15 | F8: 6 | G8: 3,9 | H8: 16 | I8: 6 | J8: 10 | K8: 17 | L8: 5 | M8: 1 | R8: 18 | S8: 3 | T8: 12 | U8: 19 | V8: 4 | W8: -
A9: 3 | B9: Ecuaciones Diferenciales | E9: Cálculo II | H9: Mecánica y Ondas | K9: Fundamentos de Economía | R9: Teología III | U9: Minor
B11: 20 | C11: 6 | D11: 15 | E11: 21 | F11: 6 | G11: 15,16 | H11: 22 | I11: 5 | J11: 2,15,16 | K11: 23 | L11: 6 | M11: 9,16 | N11: 24 | O11: 3 | P11: 7 | R11: 25 | S11: 4 | T11: -
A12: 4 | B12: Probabilidades y Estadística | E12: Electricidad y Magnetismo | H12: Termodinámica | K12: Estática | N12: Ética | R12: Minor
B14: 26 | C14: 6 | D14: 15 | E14: 27 | F14: 6 | G14: 20 | H14: 28 | I14: 6 | J14: 3 | K14: 29 | L14: 6 | R14: 30 | S14: 3 | T14: 24 | U14: 31 | V14: 4 | W14: -
A15: 5 | B15: Optimización | E15: Métodos Estadísticos para la Gestión | H15: Bases de Datos | K15: Concentración Tecnológica | R15: Filosofía de las Ciencias | U15: Minor
B17: 32 | C17: 6 | D17: 20,26 | E17: 33 | F17: 6 | G17: 20,26 | H17: 34 | I17: 6 | J17: 17 | K17: 35 | L17: 6 | M17: 17 | N17: 36 | O17: 6
A18: 6 | B18: Modelos Estocásticos | E18: Programación Matemática | H18: Contabilidad y Control de Gestión | K18: Microeconomía | N18: Concentración Tecnológica
U19: 37 | V19: 12 | W19: 170 cr
U20: Pre-Professional Practice
B21: 38 | C21: 6 | D21: 33 | E21: 39 | F21: 6 | G21: 27 | H21: 40 | I21: 6 | J21: 17, 34 | K21: 41 | L21: 6 | N21: 42 | O21: 6 | P21: 150 cr
A22: 7 | B22: Gestión de Operaciones | E22: Marketing | H22: Finanzas | K22: Concentración Tecnológica | N22: Pensamiento de Diseño Aplicado a Ingeniería
B24: 43 | C24: 9 | D24: 32,38,40 | E24: 44 | F24: 6 | G24: 27,32 | H24: 45 | I24: 6 | J24: 17 | K24: 46 | L24: 6 | M24: 34 | R24: 47 | S24: 3 | T24: -
A25: 8 | B25: Diseño y Evaluación de Proyectos Industriales | E25: Simulación | H25: Macroeconomía | K25: Gestión de Personas y Desarrollo Organizacional | R25: Opt. Arte y Lit./Hist. y Pens. Cont.
B27: # | C27: Cr | D27: Req.
B28: Nombre Curso

Sheet ICI Tit
A2: Sem | B2: 48 | C2: 6 | D2: Lic | E2: 49 | F2: 6 | G2: Lic | H2: 50 | I2: 6 | J2: Lic | K2: 51 | L2: 6 | N2: 52 | O2: 6
A3: 1 | B3: Organización Industrial | E3: Instrumentos Financieros | H3: Logistics | K3: Mención | N3: Electivo Especialidad
B5: 53 | C5: 6 | D5: Lic | E5: 54 | F5: 6 | G5: Lic | H5: 55 | I5: 4 | J5: 276 cr | K5: 56 | L5: 6 | N5: 57 | O5: 6 | Q5: 58 | R5: 2 | S5: 270 cr
A6: 2 | B6: Gestión Estratégica | E6: Econometría | H6: Proyecto Titulo 1 | K6: Mención | N6: Mención | Q6: Seminario Ética Profesional
U7: 59 | V7: 12 | W7: 282 cr
U8: Professional Practice
B9: 60 | C9: 6 | E9: 61 | F9: 6 | H9: 62 | I9: 18 | J9: 55
A10: 3 | B10: Electivo Especialidad | E10: Electivo Mención | H10: Proyecto Titulo 2
B12: # | C12: Cr | D12: Req.
B13: Nombre Curso
A16: Mención Gestión de Operaciones
A17: Sem | B17: 48 | C17: 6 | D17: Lic | E17: 49 | F17: 6 | G17: Lic | H17: 50 | I17: 6 | J17: Lic | K17: 51 | L17: 6 | M17: Lic | N17: 52 | O17: 6 | Y17: x
A18: 1 | B18: Organización Industrial | E18: Instrumentos Financieros | H18: Logistics | K18: Gestión de Operaciones en Servicios | N18: Electivo Especialidad
B20: 53 | C20: 6 | D20: Lic | E20: 54 | F20: 6 | G20: Lic | H20: 55 | I20: 4 | J20: 276 cr | K20: 56 | L20: 6 | M20: Lic | N20: 57 | O20: 6 | P20: 50 | Q20: 58 | R20: 2 | S20: 270 cr
A21: 2 | B21: Gestión Estratégica | E21: Econometría | H21: Proyecto Titulo 1 | K21: Modelamiento | N21: Estudio de Casos en Gestión de Operaciones | Q21: Seminario Ética Profesional
U22: 59 | V22: 12 | W22: 282 cr
U23: Professional Practice
B24: 60 | C24: 6 | E24: 61 | F24: 6 | H24: 62 | I24: 18 | J24: 55
A25: 3 | B25: Electivo Especialidad | E25: Electivo Mención | H25: Proyecto Titulo 2
A27: Mención Ingeniería Financiera
A28: Sem | B28: 48 | C28: 6 | D28: Lic | E28: 49 | F28: 6 | G28: Lic | H28: 50 | I28: 6 | J28: Lic | K28: 51 | L28: 6 | M28: Lic | N28: 52 | O28: 6
A29: 1 | B29: Organización Industrial | E29: Instrumentos Financieros | H29: Logistics | K29: Análisis de Estados Financieros | N29: Electivo Especialidad
B31: 53 | C31: 6 | D31: Lic | E31: 54 | F31: 6 | G31: Lic | H31: 55 | I31: 4 | J31: 276 cr | K31: 56 | L31: 6 | M31: Lic | N31: 57 | O31: 6 | P31: 49 | Q31: 58 | R31: 2 | S31: 270 cr
A32: 2 | B32: Gestión Estratégica | E32: Econometría | H32: Proyecto Titulo 1 | K32: Administración de los Riesgos Financieros | N32: Estudio de Casos en Finanzas | Q32: Seminario Ética Profesional
U33: 59 | V33: 12 | W33: 282 cr
U34: Professional Practice
B35: 60 | C35: 6 | E35: 61 | F35: 6 | H35: 62 | I35: 18 | J35: 55
A36: 3 | B36: Electivo Especialidad | E36: Electivo Mención | H36: Proyecto Titulo 2

Sheet IOC Malla
B2: Año 1 | J2: Año 2 | R2: Año 3 | Z2: Año 4 | AI2: Año 5 | AQ2: Año 6
B3: 1 | F3: 2 | J3: 1 | N3: 2 | R3: 1 | V3: 2 | Z3: 1 | AD3: 2 | AI3: 1 | AM3: 2 | AQ3: 1
A4: Curso 1 | B4: 1 | C4: 10 | D4: - | E4: - | F4: 8 | G4: 6 | H4: - | I4: 1,4,3 | J4: 14 | K4: 6 | L4: - | M4: 3,8,9 | N4: 20 | O4: 6 | P4: - | Q4: 15 | R4: 26 | S4: 6 | T4: Ib | U4: 14,23 | V4: 32 | W4: 6 | X4: Ib | Y4: 26 | Z4: 38 | AA4: 6 | AB4: Ec, Ib | AC4: 32 | AD4: 43 | AE4: 9 | AF4: Ec | AG4: 28,38,40 | AI4: 48 | AJ4: 6 | AK4: Ic(Oa) | AL4: 228 cr | AM4: 53 | AN4: 6 | AQ4: 60 | AR4: 6
B5: Álgebra e Introducción al Cálculo | F5: Álgebra Lineal | J5: Ecuaciones Diferenciales | N5: Probabilidades y Estadística | R5: Mecánica de Materiales | V5: Análisis Estructural | Z5: Hormigón Armado | AD5: Métodos Computacionales en Obras Civiles | AI5: Dynamics of Structures | AM5: Electivo Especialidad | AQ5: Electivo Especialidad
A6: Curso 2 | B6: 2 | C6: 5 | D6: ='[1]Malla base'!D6 -> 0 | E6: - | F6: 9 | G6: 6 | H6: - | I6: 1,4 | J6: 15 | K6: 6 | L6: - | M6: 3,9 | N6: 21 | O6: 6 | P6: ='[1]Malla base'!P6 -> 0 | Q6: 15,16 | R6: 27 | S6: 6 | U6: 15 | V6: 33 | W6: 6 | Y6: 9 | Z6: 39 | AA6: 6 | AC6: 26 | AD6: 44 | AE6: 6 | AG6: 33,35 | AI6: 49 | AJ6: 6 | AL6: 228 cr, 32 | AM6: 54 | AN6: 6 | AO6: Ia,Ec | AP6: 240 cr | AQ6: 61 | AR6: 6 | AS6: Ec,Ob
B7: Fundamentos de Química | F7: Cálculo I | J7: Cálculo II | N7: Electricidad y Magnetismo | R7: Optimización | V7: Topografía Aplicada | Z7: Introducción a la Geomecánica | AD7: Métodos y Técnicas de Construcción | AI7: Diseño en Acero | AM7: Tecnología del Hormigón | AQ7: Proyecto Civil
A8: Curso 3 | B8: 3 | C8: 5 | D8: - | E8: - | F8: 10 | G8: 6 | I8: 1 | J8: 16 | K8: 6 | L8: ='[1]Malla base'!L8 -> 0 | M8: 10 | N8: 22 | O8: 5 | P8: ='[1]Malla base'!P8 -> 0 | Q8: 2,15,16 | R8: 28 | S8: 6 | U8: 3,15 | V8: 34 | W8: 6 | X8: Ic(Ea) | Y8: 14,23 | Z8: 40 | AA8: 6 | AC8: 34 | AD8: 45 | AE8: 6 | AG8: 20,40 | AI8: 50 | AJ8: 6 | AK8: Ec,Ob | AL8: 43,44 | AM8: 55 | AN8: 4 | AP8: 276 cr | AQ8: 62 | AR8: 18 | AT8: 55
B9: Programación | F9: Introducción a la Mecánica | J9: Mecánica y Ondas | N9: Termodinámica | R9: Métodos Numéricos | V9: Fluid Mechanics | Z9: Hidráulica | AD9: Hidrología | AI9: Evaluación de Proyectos de Ingeniería | AM9: Proyecto de Título 1 | AQ9: Proyecto de Título 2
A10: Curso 4 | B10: 4 | C10: 1 | D10: - | E10: - | F10: 11 | G10: 5 | H10: ='[1]Malla base'!H10 -> 0 | I10: 4 | J10: 17 | K10: 5 | L10: ='[1]Malla base'!L10 -> 0 | M10: 1 | N10: 23 | O10: 6 | P10: - | Q10: 9,16 | R10: 29 | S10: 6 | V10: 35 | W10: 6 | X10: Ib | Y10: 2 | Z10: 41 | AA10: 6 | AD10: 46 | AE10: 6 | AG10: 17,20 | AI10: 51 | AJ10: 6 | AM10: 56 | AN10: 6
B11: Bases para el Estudio de Ingeniería | F11: Biología de los Microorganismos | J11: Fundamentos de Economía | N11: Estática | R11: Concentración Tecnológica | V11: Materiales de Construcción | Z11: Concentración Tecnológica | AD11: Sistemas de Transporte | AI11: Mención | AM11: Mención
A12: Curso 5 | B12: 5 | C12: 3 | E12: - | N12: 24 | O12: 3 | Q12: 7 | V12: 36 | W12: 6 | Z12: 42 | AA12: 6 | AB12: Ib(Ea) | AC12: 150 cr | AI12: 52 | AJ12: 6 | AM12: 57 | AN12: 6
B13: Taller de Proyectos de Ingeniería | N13: Ética | V13: Concentración Tecnológica | Z13: Pensamiento de Diseño Aplicado a Ingeniería | AI13: Mención | AM13: Mención
A14: Curso 6 | B14: 6 | C14: 3 | D14: - | E14: - | F14: 12 | G14: 3 | H14: - | I14: 6 | J14: 18 | K14: 3 | L14: - | M14: 12 | N14: 25 | O14: 4 | P14: - | Q14: - | R14: 30 | S14: 3 | T14: - | U14: 24 | AD14: 47 | AE14: 3 | AF14: - | AG14: - | AM14: 58 | AN14: 2 | AO14: ='[1]Malla base'!AO14 -> 0 | AP14: 270 cr
B15: Teología I | F15: Teología II | J15: Teología III | N15: Minor | R15: Filosofía de las Ciencias | AD15: Optativo Arte y Literatura/Historia y Pensamiento Contemporáneo | AM15: Seminario Ética Profesional
A16: Curso 7 | B16: 7 | C16: 3 | D16: - | E16: - | F16: 13 | G16: 3 | H16: - | I16: - | J16: 19 | K16: 4 | L16: - | M16: - | R16: 31 | S16: 4 | T16: - | U16: -
B17: Antropología Filosófica | F17: Optativo Arte y Literatura/Historia y Pensamiento Contemporáneo | J17: Minor | R17: Minor
X18: 37 | Y18: 12 | Z18: ='[1]Malla base'!Z18 -> 0 | AA18: 170 cr | AO18: 59 | AP18: 12 | AQ18: ='[1]Malla base'!AQ18 -> 0 | AR18: 282 cr
E19: * | F19: APR | X19: Pre-Professional Practice | AO19: Professional Practice
E20: Inglés ALTE 3
B22: # | C22: SCT | D22: HT | E22: Req.
B23: Nombre Curso
B25: Año 1 | J25: Año 2 | R25: Año 3 | Z25: Año 4 | AI25: Año 5 | AQ25: Año 6
B26: =C4+C6+C8+C10+C12+C14+C16+G4+G6+G8+G10+G14+G16 -> 59 | J26: =K4+K6+K8+K10+K14+K16+O4+O6+O8+O10+O12+O14 -> 60 | R26: =S4+S6+S8+S10+S14+S16+W4+W6+W8+W10+W12+Y18 -> 73 | Z26: =AA4+AA6+AA8+AA10+AA12+AA14+AE4+AE6+AE8+AE10+AE14 -> 60 | AI26: =AJ4+AJ6+AJ8+AJ10+AJ12+AN4+AN6+AN8+AN10+AN12+AN14+AP18 -> 72 | AQ26: =AR4+AR6+AR8 -> 30

Sheet IOC Lic
A2: Sem | B2: 1 | C2: 10 | D2: - | E2: 2 | F2: 5 | G2: - | H2: 3 | I2: 5 | J2: - | K2: 4 | L2: 1 | M2: - | N2: 5 | O2: 3 | P2: - | R2: 6 | S2: 3 | T2: - | U2: 7 | V2: 3 | W2: -
A3: 1 | B3: Álgebra e Introducción al Cálculo | E3: Fundamentos de Química | H3: Programación | K3: Bases para el Estudio de Ingeniería | N3: Taller de Proyectos de Ingeniería | R3: Teología I | U3: Antropología Filosófica | Y3: * | Z3: APR
Y4: Inglés ALTE 3
B5: 8 | C5: 6 | D5: 1,4,3 | E5: 9 | F5: 6 | G5: 1,4 | H5: 10 | I5: 6 | J5: 1 | K5: 11 | L5: 5 | M5: 4 | R5: 12 | S5: 3 | T5: 6 | U5: 13 | V5: 3 | W5: -
A6: 2 | B6: Álgebra Lineal | E6: Cálculo I | H6: Introducción a la Mecánica | K6: Biología de los Microorganismos | R6: Teología II | U6: Opt. Arte y Lit./Hist. y Pens. Cont.
B8: 14 | C8: 6 | D8: 3,8,9 | E8: 15 | F8: 6 | G8: 3,9 | H8: 16 | I8: 6 | J8: 10 | K8: 17 | L8: 5 | M8: 1 | R8: 18 | S8: 3 | T8: 12 | U8: 19 | V8: 4 | W8: -
A9: 3 | B9: Ecuaciones Diferenciales | E9: Cálculo II | H9: Mecánica y Ondas | K9: Fundamentos de Economía | R9: Teología III | U9: Minor
B11: 20 | C11: 6 | D11: 15 | E11: 21 | F11: 6 | G11: 15,16 | H11: 22 | I11: 5 | J11: 2,15,16 | K11: 23 | L11: 6 | M11: 9,16 | N11: 24 | O11: 3 | P11: 7 | R11: 25 | S11: 4 | T11: -
A12: 4 | B12: Probabilidades y Estadística | E12: Electricidad y Magnetismo | H12: Termodinámica | K12: Estática | N12: Ética | R12: Minor
B14: 26 | C14: 6 | D14: 14,23 | E14: 27 | F14: 6 | G14: 15 | H14: 28 | I14: 6 | J14: 3,15 | K14: 29 | L14: 6 | R14: 30 | S14: 3 | T14: 24 | U14: 31 | V14: 4 | W14: -
A15: 5 | B15: Mecánica de Materiales | E15: Optimización | H15: Métodos Numéricos | K15: Concentración Tecnológica | R15: Filosofía de las Ciencias | U15: Minor
B17: 32 | C17: 6 | D17: 26 | E17: 33 | F17: 6 | G17: 9 | H17: 34 | I17: 6 | J17: 14,23 | K17: 35 | L17: 6 | M17: 2 | N17: 36 | O17: 6
A18: 6 | B18: Análisis Estructural | E18: Topografía Aplicada | H18: Fluid Mechanics | K18: Materiales de Construcción | N18: Concentración Tecnológica
U19: 37 | V19: 12 | W19: 170 cr
U20: Pre-Professional Practice
B21: 38 | C21: 6 | D21: 32 | E21: 39 | F21: 6 | G21: 26 | H21: 40 | I21: 6 | J21: 34 | K21: 41 | L21: 6 | N21: 42 | O21: 6 | P21: 150 cr
A22: 7 | B22: Hormigón Armado | E22: Introducción a la Geomecánica | H22: Hidráulica | K22: Concentración Tecnológica | N22: Pensamiento de Diseño Aplicado a Ingeniería
B24: 43 | C24: 9 | D24: 28,38,40 | E24: 44 | F24: 6 | G24: 33,35 | H24: 45 | I24: 6 | J24: 20,40 | K24: 46 | L24: 6 | M24: 17,20 | R24: 47 | S24: 3 | T24: -
A25: 8 | B25: Métodos Computacionales en Obras Civiles | E25: Métodos y Técnicas de Construcción | H25: Hidrología | K25: Sistemas de Transporte | R25: Opt. Arte y Lit./Hist. y Pens. Cont.
B27: # | C27: Cr | D27: Req.
B28: Nombre Curso

Sheet IOC Tit
A2: Sem | B2: 48 | C2: 6 | D2: 228 | E2: 49 | F2: 6 | G2: 228 | H2: 50 | I2: 6 | J2: 43,44 | K2: 51 | L2: 6 | N2: 52 | O2: 6
A3: 1 | B3: Dynamics of Structures | E3: Diseño en Acero | H3: Evaluación de Proyectos de Ingeniería | K3: Mención | N3: Mención
B5: 53 | C5: 6 | E5: 54 | F5: 6 | G5: 240 | H5: 55 | I5: 4 | J5: 276 cr | K5: 56 | L5: 6 | N5: 57 | O5: 6 | Q5: 58 | R5: 2 | S5: 270 cr
A6: 2 | B6: Electivo Especialidad | E6: Tecnología del Hormigón | H6: Proyecto Titulo 1 | K6: Mención | N6: Mención | Q6: Seminario Ética Profesional
U7: 59 | V7: 12 | W7: 282 cr
U8: Professional Practice
B9: 60 | C9: 6 | E9: 61 | F9: 6 | H9: 62 | I9: 18 | J9: 55
A10: 3 | B10: Electivo Especialidad | E10: Proyecto Civil | H10: Proyecto Titulo 2
B12: # | C12: Cr | D12: Req.
B13: Nombre Curso
A15: Mención Estructuras
A16: Sem | B16: 48 | C16: 6 | D16: 228 cr | E16: 49 | F16: 6 | G16: 228 cr | H16: 50 | I16: 6 | J16: 43,44 | K16: 51 | L16: 6 | M16: 228 cr | N16: 52 | O16: 6 | P16: 32,43
A17: 1 | B17: Dynamics of Structures | E17: Diseño en Acero | H17: Evaluación de Proyectos de Ingeniería | K17: Fundaciones | N17: Finite Elements
B19: 53 | C19: 6 | E19: 54 | F19: 6 | G19: 240 cr | H19: 55 | I19: 4 | J19: 276 cr | K19: 56 | L19: 6 | M19: 240 cr | N19: 57 | O19: 6 | P19: 38,48 | Q19: 58 | R19: 2 | S19: 270 cr
A20: 2 | B20: Electivo Especialidad | E20: Tecnología del Hormigón | H20: Proyecto Titulo 1 | K20: Hormigón Armado Avanzado | N20: Diseño Sismorresistente | Q20: Seminario Ética Profesional
U21: 59 | V21: 12 | W21: 282 cr
U22: Professional Practice
B23: 60 | C23: 6 | E23: 61 | F23: 6 | G23: 57 | H23: 62 | I23: 18 | J23: 55
A24: 3 | B24: Electivo Especialidad | E24: Proyecto Civil (Mención Estructuras) | H24: Proyecto Titulo 2
A26: Mención Desarrollo de Proyectos de Infraestructura
A27: Sem | B27: 48 | C27: 6 | D27: 228 cr | E27: 49 | F27: 6 | G27: 228 cr | H27: 50 | I27: 6 | J27: 43,44 | K27: 51 | L27: 6 | M27: 228 cr | N27: 52 | O27: 6 | P27: 45
A28: 1 | B28: Dynamics of Structures | E28: Diseño en Acero | H28: Evaluación de Proyectos de Ingeniería | K28: Cost Engineering | N28: Hidráulica Urbana
B30: 53 | C30: 6 | E30: 54 | F30: 6 | G30: 240 cr | H30: 55 | I30: 4 | J30: 276 cr | K30: 56 | L30: 6 | M30: 51 | N30: 57 | O30: 6 | P30: 44,46 | Q30: 58 | R30: 2 | S30: 270 cr
A31: 2 | B31: Electivo Especialidad | E31: Tecnología del Hormigón | H31: Proyecto Titulo 1 | K31: Administración y Control de Proyectos | N31: Ingeniería Vial | Q31: Seminario Ética Profesional
U32: 59 | V32: 12 | W32: 282 cr
U33: Professional Practice
B34: 60 | C34: 6 | E34: 61 | F34: 6 | G34: 56 | H34: 62 | I34: 18 | J34: 55
A35: 3 | B35: Electivo Especialidad | E35: Proyecto Civil (Mención DPI) | H35: Proyecto Titulo 2

Sheet ICE Malla
B2: Año 1 | J2: Año 2 | R2: Año 3 | Z2: Año 4 | AI2: Año 5 | AQ2: Año 6
B3: 1 | F3: 2 | J3: 1 | N3: 2 | R3: 1 | V3: 2 | Z3: 1 | AD3: 2 | AI3: 1 | AM3: 2 | AQ3: 1
A4: Curso 1 | B4: 1 | C4: 10 | D4: - | E4: - | F4: 8 | G4: 6 | H4: - | I4: 1,4,3 | J4: 14 | K4: 6 | L4: - | M4: 3,8,9 | N4: 20 | O4: 6 | P4: - | Q4: 15 | R4: 26 | S4: 6 | U4: 14,21 | V4: 32 | W4: 6 | Y4: 26 | Z4: 38 | AA4: 6 | AC4: 27,32 | AD4: 43 | AE4: 9 | AF4: Ib | AG4: 200 cr. | AI4: 48 | AJ4: 6 | AL4: 44 | AM4: 53 | AN4: 6 | AO4: Ic(Oa) | AP4: 20,27 | AQ4: 60 | AR4: 6
B5: Álgebra e Introducción al Cálculo | F5: Álgebra Lineal | J5: Ecuaciones Diferenciales | N5: Probabilidades y Estadística | R5: Análisis de Circuitos | V5: Sistemas Electrónicos | Z5: Sistemas Electrónicos Avanzados | AD5: Proyecto de Diseño Eléctrico | AI5: Electrónica de Potencia | AM5: Artificial Intelligence | AQ5: Electivo
A6: Curso 2 | B6: 2 | C6: 5 | D6: ='Malla base'!D6 -> Ea | E6: - | F6: 9 | G6: 6 | H6: - | I6: 1,4 | J6: 15 | K6: 6 | L6: - | M6: 3,9 | N6: 21 | O6: 6 | P6: ='Malla base'!P6 -> Eb | Q6: 15,16 | R6: 27 | S6: 6 | T6: Ia | U6: 14 | V6: 33 | W6: 6 | X6: Ib | Y6: 27 | Z6: 39 | AA6: 6 | AB6: Ec,Ib | AC6: 20,33 | AD6: 44 | AE6: 6 | AF6: Ec | AG6: 16,27 | AI6: 49 | AJ6: 6 | AK6: Ec, Ob | AL6: 45 | AM6: 54 | AN6: 6 | AP6: 39 | AQ6: 61 | AR6: 6
B7: Fundamentos de Química | F7: Cálculo I | J7: Cálculo II | N7: Electricidad y Magnetismo | R7: Señales y Sistemas | V7: Procesamiento de Señales | Z7: Introducción a las Comunicaciones | AD7: Control Automático | AI7: Sistemas de Potencia | AM7: Redes de Comunicación | AQ7: Electivo
A8: Curso 3 | B8: 3 | C8: 5 | D8: - | E8: - | F8: 10 | G8: 6 | H8: - | I8: 1 | J8: 16 | K8: 6 | L8: ='Malla base'!L8 -> Eb | M8: 10 | N8: 22 | O8: 5 | P8: ='Malla base'!P8 -> Eb | Q8: 2,15,16 | R8: 28 | S8: 6 | U8: 8 | V8: 34 | W8: 6 | X8: Ic(Ec) | Y8: 21 | Z8: 40 | AA8: 6 | AB8: Ec | AC8: 22,26 | AD8: 45 | AE8: 6 | AF8: Ec | AG8: 40 | AI8: 50 | AJ8: 6 | AK8: Ec,Ob | AL8: 34,40 | AM8: 55 | AN8: 4 | AP8: 276 cr | AQ8: 62 | AR8: 18 | AT8: 55
B9: Programación | F9: Introducción a la Mecánica | J9: Mecánica y Ondas | N9: Termodinámica | R9: Sistemas Digitales | V9: Optical Systems | Z9: Conversión de Energía | AD9: Potencia Eléctrica | AI9: Fundamentos de Energías Renovables | AM9: Proyecto de Título 1 | AQ9: Proyecto de Título 2
A10: Curso 4 | B10: 4 | C10: 1 | D10: - | E10: - | F10: 11 | G10: 5 | H10: ='Malla base'!H10 -> Ea | I10: 4 | J10: 17 | K10: 5 | L10: ='ICI Malla'!L10 -> Ia | M10: 1 | N10: 23 | O10: 6 | P10: - | Q10: 9,16 | R10: 29 | S10: 6 | V10: 35 | W10: 6 | Y10: 26,28 | Z10: 41 | AA10: 6 | AD10: 46 | AE10: 6 | AG10: 39 | AI10: 51 | AJ10: 6 | AL10: 45 | AM10: 56 | AN10: 6 | AP10: 49
B11: Bases para el Estudio de Ingeniería | F11: Biología de los Microorganismos | J11: Fundamentos de Economía | N11: Estática | R11: Concentración Tecnológica | V11: Sistemas Digitales Avanzados | Z11: Concentración Tecnológica | AD11: Comunicaciones Digitales | AI11: Mercados Eléctricos | AM11: Protecciones Eléctricas
A12: Curso 5 | B12: 5 | C12: 3 | E12: - | N12: 24 | O12: 3 | Q12: 7 | V12: 36 | W12: 6 | Z12: 42 | AA12: 6 | AB12: Ib(Ea) | AC12: 150 cr | AI12: 52 | AJ12: 6 | AM12: 57 | AN12: 6
B13: Taller de Proyectos de Ingeniería | N13: Ética | V13: Concentración Tecnológica | Z13: Pensamiento de Diseño Aplicado a Ingeniería | AI13: Electivo | AM13: Electivo
A14: Curso 6 | B14: 6 | C14: 3 | D14: - | E14: - | F14: 12 | G14: 3 | H14: - | I14: 6 | J14: 18 | K14: 3 | L14: - | M14: 12 | N14: 25 | O14: 4 | P14: - | Q14: - | R14: 30 | S14: 3 | T14: - | U14: 24 | AD14: 47 | AE14: 3 | AF14: - | AG14: - | AM14: 58 | AN14: 2 | AO14: Ec | AP14: 270 cr
B15: Teología I | F15: Teología II | J15: Teología III | N15: Minor | R15: Filosofía de las Ciencias | AD15: Optativo Arte y Literatura/Historia y Pensamiento Contemporáneo | AM15: Seminario Ética Profesional
A16: Curso 7 | B16: 7 | C16: 3 | D16: - | E16: - | F16: 13 | G16: 3 | H16: - | I16: - | J16: 19 | K16: 4 | L16: - | M16: - | R16: 31 | S16: 4 | T16: - | U16: -
B17: Antropología Filosófica | F17: Optativo Arte y Literatura/Historia y Pensamiento Contemporáneo | J17: Minor | R17: Minor
X18: 37 | Y18: 12 | Z18: ='Malla base'!Z18 -> Ic(Ea) | AA18: 170 cr | AO18: 59 | AP18: 12 | AQ18: ='Malla base'!AQ18 -> Ic(Eb, Ob) | AR18: 282 cr
E19: * | F19: APR | X19: Pre-Professional Practice | AO19: Professional Practice
E20: Inglés ALTE 3
B22: # | C22: SCT | D22: HT | E22: Req.
B23: Nombre Curso
B26: Año 1 | J26: Año 2 | R26: Año 3 | Z26: Año 4 | AI26: Año 5 | AQ26: Año 6
B27: =C4+C6+C8+C10+C12+C14+C16+G4+G6+G8+G10+G14+G16 -> 59 | J27: =K4+K6+K8+K10+K14+K16+O4+O6+O8+O10+O12+O14 -> 60 | R27: 61 | Z27: =AA4+AA6+AA8+AA10+AA12+AA14+AE4+AE6+AE8+AE10+AE14 -> 60 | AI27: =AJ4+AJ6+AJ8+AJ10+AJ12+AN4+AN6+AN8+AN10+AN12+AN14+AP18 -> 72 | AQ27: =AR4+AR6+AR8 -> 30

Sheet ICE Lic
A2: Sem | B2: 1 | C2: 10 | D2: - | E2: 2 | F2: 5 | G2: - | H2: 3 | I2: 5 | J2: - | K2: 4 | L2: 1 | M2: - | N2: 5 | O2: 3 | P2: - | R2: 6 | S2: 3 | T2: - | U2: 7 | V2: 3 | W2: -
A3: 1 | B3: Álgebra e Introducción al Cálculo | E3: Fundamentos de Química | H3: Programación | K3: Bases para el Estudio de Ingeniería | N3: Taller de Proyectos de Ingeniería | R3: Teología I | U3: Antropología Filosófica | Y3: * | Z3: APR
Y4: Inglés ALTE 3
B5: 8 | C5: 6 | D5: 1,4,3 | E5: 9 | F5: 6 | G5: 1,4 | H5: 10 | I5: 6 | J5: 1 | K5: 11 | L5: 5 | M5: 4 | R5: 12 | S5: 3 | T5: 6 | U5: 13 | V5: 3 | W5: -
A6: 2 | B6: Álgebra Lineal | E6: Cálculo I | H6: Introducción a la Mecánica | K6: Biología de los Microorganismos | R6: Teología II | U6: Opt. Arte y Lit./Hist. y Pens. Cont.
B8: 14 | C8: 6 | D8: 3,8,9 | E8: 15 | F8: 6 | G8: 3,9 | H8: 16 | I8: 6 | J8: 10 | K8: 17 | L8: 5 | M8: 1 | R8: 18 | S8: 3 | T8: 12 | U8: 19 | V8: 4 | W8: -
A9: 3 | B9: Ecuaciones Diferenciales | E9: Cálculo II | H9: Mecánica y Ondas | K9: Fundamentos de Economía | R9: Teología III | U9: Minor
B11: 20 | C11: 6 | D11: 15 | E11: 21 | F11: 6 | G11: 15,16 | H11: 22 | I11: 5 | J11: 2,15,16 | K11: 23 | L11: 6 | M11: 9,16 | N11: 24 | O11: 3 | P11: 7 | R11: 25 | S11: 4 | T11: -
A12: 4 | B12: Probabilidades y Estadística | E12: Electricidad y Magnetismo | H12: Termodinámica | K12: Estática | N12: Ética | R12: Minor
B14: 26 | C14: 6 | D14: 14,21 | E14: 27 | F14: 6 | G14: 14 | H14: 28 | I14: 6 | J14: 8 | K14: 29 | L14: 6 | R14: 30 | S14: 3 | T14: 24 | U14: 31 | V14: 4 | W14: -
A15: 5 | B15: Análisis de Circuitos | E15: Señales y Sistemas | H15: Sistemas Digitales | K15: Concentración Tecnológica | R15: Filosofía de las Ciencias | U15: Minor
B17: 32 | C17: 6 | D17: 26 | E17: 33 | F17: 6 | G17: 27 | H17: 34 | I17: 6 | J17: 21 | K17: 35 | L17: 6 | M17: 26,28 | N17: 36 | O17: 6
A18: 6 | B18: Sistemas Electrónicos | E18: Procesamiento de Señales | H18: Optical Systems | K18: Sistemas Digitales Avanzados | N18: Concentración Tecnológica
U19: 37 | V19: 12 | W19: 170 cr
U20: Pre-Professional Practice
B21: 38 | C21: 6 | D21: 27,32 | E21: 39 | F21: 6 | G21: 20,33 | H21: 40 | I21: 6 | J21: 22,26 | K21: 41 | L21: 6 | N21: 42 | O21: 6 | P21: 150 cr
A22: 7 | B22: Sistemas Electrónicos Avanzados | E22: Introducción a las Comunicaciones | H22: Conversión de Energía | K22: Concentración Tecnológica | N22: Pensamiento deDiseño Aplicado a Ingeniería
B24: 43 | C24: 9 | D24: 200 cr | E24: 44 | F24: 6 | G24: 16,27 | H24: 45 | I24: 6 | J24: 40 | K24: 46 | L24: 6 | M24: 39 | R24: 47 | S24: 3 | T24: -
A25: 8 | B25: Proyecto de Diseño Eléctrico | E25: Control Automático | H25: Potencia Eléctrica | K25: Comunicaciones Digitales | R25: Opt. Arte y Lit./Hist. y Pens. Cont.
B27: # | C27: Cr | D27: Req.
B28: Nombre Curso

Sheet ICE Tit
A2: Sem | B2: 48 | C2: 6 | D2: 45 | E2: 49 | F2: 6 | G2: 46 | H2: 50 | I2: 6 | J2: 34,40 | K2: 51 | L2: 6 | M2: 45 | N2: 52 | O2: 6
A3: 1 | B3: Electrónica de Potencia | E3: Sistemas de Potencia | H3: Fundamentos de Energías Renovables | K3: Mercados Eléctricos | N3: Electivo Especialidad
B5: 52 | C5: 6 | D5: 20,27 | E5: 54 | F5: 6 | G5: 50 | H5: 55 | I5: 4 | J5: 276 cr | K5: 56 | L5: 6 | N5: 57 | O5: 6 | Q5: 58 | R5: 2 | S5: 270 cr
A6: 2 | B6: Artificial Intelligence | E6: Redes de Comunicación | H6: Proyecto Titulo 1 | K6: Protecciones Eléctricas | N6: Electivo Especialidad | Q6: Seminario Ética Profesional
U7: 59 | V7: 12 | W7: 282 cr
U8: Professional Practice
B9: 60 | C9: 6 | E9: 61 | F9: 6 | H9: 62 | I9: 18 | J9: 55
A10: 3 | B10: Electivo Especialidad | E10: Electivo Especialidad | H10: Proyecto Titulo 2
B12: # | C12: Cr | D12: Req.
B13: Nombre Curso

Sheet ICC Malla
B2: Año 1 | J2: Año 2 | R2: Año 3 | Z2: Año 4 | AI2: Año 5 | AQ2: Año 6
B3: 1 | F3: 2 | J3: 1 | N3: 2 | R3: 1 | V3: 2 | Z3: 1 | AD3: 2 | AI3: 1 | AM3: 2 | AQ3: 1
A4: Curso 1 | B4: 1 | C4: 10 | D4: - | E4: - | F4: 8 | G4: 6 | H4: - | I4: 1,4,3 | J4: 14 | K4: 6 | L4: - | M4: 3,8,9 | N4: 20 | O4: 6 | P4: - | Q4: 15 | R4: 26 | S4: 6 | T4: - | U4: 3 | V4: 32 | W4: 6 | X4: - | Y4: 27 | Z4: 38 | AA4: 6 | AB4: Ic | AC4: 34 | AD4: 43 | AE4: 9 | AF4: Ec | AG4: 20,38,40 | AI4: 48 | AJ4: 6 | AK4: Ic(Oa) | AL4: 43 | AM4: 53 | AN4: 6 | AP4: 43 | AQ4: 60 | AR4: 6 | AS4: Ec, Ob | AT4: 53
B5: Álgebra e Introducción al Cálculo | F5: Álgebra Lineal | J5: Ecuaciones Diferenciales | N5: Probabilidades y Estadística | R5: Paradigmas de Programación | V5: Sistemas Operativos y Redes | Z5: Algorithms and Competitive Programming | AD5: Proyecto de Desarrollo de Software | AI5: Software Design | AM5: Gestión de Proyectos de Software | AQ5: Emprendimiento e Innovación en Software
A6: Curso 2 | B6: 2 | C6: 5 | D6: ='[2]Malla base'!D6 -> 0 | E6: - | F6: 9 | G6: 6 | H6: - | I6: 1,4 | J6: 15 | K6: 6 | L6: - | M6: 3,9 | N6: 21 | O6: 6 | P6: ='[2]Malla base'!P6 -> 0 | Q6: 15,16 | R6: 27 | S6: 6 | T6: - | U6: 3 | V6: 33 | W6: 6 | X6: - | Y6: 21 | Z6: 39 | AA6: 6 | AB6: Ia | AC6: 27 | AD6: 44 | AE6: 6 | AF6: - | AG6: 40 | AI6: 49 | AJ6: 6 | AK6: Ic(Ea) | AL6: 43 | AM6: 54 | AN6: 6 | AO6: Ic(Eb) | AP6: 48 | AQ6: 61 | AR6: 6
B7: Fundamentos de Química | F7: Cálculo I | J7: Cálculo II | N7: Electricidad y Magnetismo | R7: Programación de Bajo Nivel | V7: Arquitectura de Computadores | Z7: Sistemas Embebidos | AD7: Aplicaciones Móviles | AI7: User Experience Design | AM7: Software Architecture | AQ7: Electivo Especialidad
A8: Curso 3 | B8: 3 | C8: 5 | D8: - | E8: - | F8: 10 | G8: 6 | H8: - | I8: 1 | J8: 16 | K8: 6 | L8: ='[2]Malla base'!L8 -> 0 | M8: 10 | N8: 22 | O8: 5 | P8: ='[2]Malla base'!P8 -> 0 | Q8: 2,15,16 | R8: 28 | S8: 6 | T8: Ib | U8: 3,9 | V8: 34 | W8: 6 | X8: Ib | Y8: 27 | Z8: 40 | AA8: 6 | AB8: Ic | AC8: 26,35 | AD8: 45 | AE8: 6 | AG8: 20,27 | AI8: 50 | AJ8: 6 | AL8: 43 | AM8: 55 | AN8: 4 | AP8: 276 cr | AQ8: 62 | AR8: 18 | AT8: 55
B9: Programación | F9: Introducción a la Mecánica | J9: Mecánica y Ondas | N9: Termodinámica | R9: Autómatas y Computabilidad | V9: Estructuras de Datos y Algoritmos | Z9: Web Technologies | AD9: Artificial Intelligence | AI9: Diseño de Software Verificable | AM9: Proyecto de Título 1 | AQ9: Proyecto de Título 2
A10: Curso 4 | B10: 4 | C10: 1 | D10: - | E10: - | F10: 11 | G10: 5 | H10: ='[2]Malla base'!H10 -> 0 | I10: 4 | J10: 17 | K10: 5 | L10: ='[2]Malla base'!L10 -> 0 | M10: 1 | N10: 23 | O10: 6 | P10: - | Q10: 9,16 | R10: 29 | S10: 6 | V10: 35 | W10: 6 | X10: - | Y10: 3 | Z10: 41 | AA10: 6 | AD10: 46 | AE10: 6 | AF10: Ec | AG10: 40 | AI10: 51 | AJ10: 6 | AK10: Ec | AL10: 43 | AM10: 56 | AN10: 6
B11: Bases para el Estudio de Ingeniería | F11: Biología de los Microorganismos | J11: Fundamentos de Economía | N11: Estática | R11: Concentración Tecnológica | V11: Bases de Datos | Z11: Concentración Tecnológica | AD11: Introducción a la Ingeniería de Software | AI11: Almacenamiento y Procesamiento Masivo de Datos | AM11: Electivo Especialidad
A12: Curso 5 | B12: 5 | C12: 3 | E12: - | N12: 24 | O12: 3 | Q12: 7 | V12: 36 | W12: 6 | Z12: 42 | AA12: 6 | AB12: Ib(Ea) | AC12: 150 cr | AI12: 52 | AJ12: 6 | AM12: 57 | AN12: 6
B13: Taller de Proyectos de Ingeniería | N13: Ética | V13: Concentración Tecnológica | Z13: Pensamiento de Diseño Aplicado a Ingeniería | AI13: Electivo Especialidad | AM13: Electivo Especialidad
A14: Curso 6 | B14: 6 | C14: 3 | D14: - | E14: - | F14: 12 | G14: 3 | H14: - | I14: 6 | J14: 18 | K14: 3 | L14: - | M14: 12 | N14: 25 | O14: 4 | P14: - | Q14: - | R14: 30 | S14: 3 | T14: - | U14: 24 | AD14: 47 | AE14: 3 | AF14: - | AG14: - | AM14: 58 | AN14: 2 | AO14: ='[2]Malla base'!AO14 -> 0 | AP14: 270 cr
B15: Teología I | F15: Teología II | J15: Teología III | N15: Minor | R15: Filosofía de las Ciencias | AD15: Optativo Arte y Literatura/Historia y Pensamiento Contemporáneo | AM15: Seminario Ética Profesional
A16: Curso 7 | B16: 7 | C16: 3 | D16: - | E16: - | F16: 13 | G16: 3 | H16: - | I16: - | J16: 19 | K16: 4 | L16: - | M16: - | R16: 31 | S16: 4 | T16: - | U16: -
B17: Antropología Filosófica | F17: Optativo Arte y Literatura/Historia y Pensamiento Contemporáneo | J17: Minor | R17: Minor
X18: 37 | Y18: 12 | Z18: ='[2]Malla base'!Z18 -> 0 | AA18: 170 cr | AO18: 59 | AP18: 12 | AQ18: ='[2]Malla base'!AQ18 -> 0 | AR18: 282 cr
E19: * | F19: APR | X19: Pre-Professional Practice | AO19: Professional Practice
E20: Inglés ALTE 3
B22: # | C22: SCT | D22: HT | E22: Req.
B23: Nombre Curso

Sheet ICC Lic
A2: Sem | B2: 1 | C2: 10 | D2: - | E2: 2 | F2: 5 | G2: - | H2: 3 | I2: 5 | J2: - | K2: 4 | L2: 1 | M2: - | N2: 5 | O2: 3 | P2: - | R2: 6 | S2: 3 | T2: - | U2: 7 | V2: 3 | W2: -
A3: 1 | B3: Álgebra e Introducción al Cálculo | E3: Fundamentos de Química | H3: Programación | K3: Bases para el Estudio de Ingeniería | N3: Taller de Proyectos de Ingeniería | R3: Teología I | U3: Antropología Filosófica | Y3: * | Z3: APR
Y4: Inglés ALTE 3
B5: 8 | C5: 6 | D5: 1,4,3 | E5: 9 | F5: 6 | G5: 1,4 | H5: 10 | I5: 6 | J5: 1 | K5: 11 | L5: 5 | M5: 4 | R5: 12 | S5: 3 | T5: 6 | U5: 13 | V5: 3 | W5: -
A6: 2 | B6: Álgebra Lineal | E6: Cálculo I | H6: Introducción a la Mecánica | K6: Biología de los Microorganismos | R6: Teología II | U6: Opt. Arte y Lit./Hist. y Pens. Cont.
B8: 14 | C8: 6 | D8: 3,8,9 | E8: 15 | F8: 6 | G8: 3,9 | H8: 16 | I8: 6 | J8: 10 | K8: 17 | L8: 5 | M8: 1 | R8: 18 | S8: 3 | T8: 12 | U8: 19 | V8: 4 | W8: -
A9: 3 | B9: Ecuaciones Diferenciales | E9: Cálculo II | H9: Mecánica y Ondas | K9: Fundamentos de Economía | R9: Teología III | U9: Minor
B11: 20 | C11: 6 | D11: 15 | E11: 21 | F11: 6 | G11: 15,16 | H11: 22 | I11: 5 | J11: 2,15,16 | K11: 23 | L11: 6 | M11: 9,16 | N11: 24 | O11: 3 | P11: 7 | R11: 25 | S11: 4 | T11: -
A12: 4 | B12: Probabilidades y Estadística | E12: Electricidad y Magnetismo | H12: Termodinámica | K12: Estática | N12: Ética | R12: Minor
B14: 26 | C14: 6 | D14: 3 | E14: 27 | F14: 6 | G14: 3 | H14: 28 | I14: 6 | J14: 3,9 | K14: 29 | L14: 6 | R14: 30 | S14: 3 | T14: 24 | U14: 31 | V14: 4 | W14: -
A15: 5 | B15: Paradigmas de Programación | E15: Programación de Bajo Nivel | H15: Autómatas y Computabilidad | K15: Concentración Tecnológica | R15: Filosofía de las Ciencias | U15: Minor
B17: 32 | C17: 6 | D17: 27 | E17: 33 | F17: 6 | G17: 21 | H17: 34 | I17: 6 | J17: 27 | K17: 35 | L17: 6 | M17: 3 | N17: 36 | O17: 6
A18: 6 | B18: Sistemas Operativos y Redes | E18: Arquitectura de Computadores | H18: Estructuras de Datos y Algoritmos | K18: Bases de Datos | N18: Concentración Tecnológica
U19: 37 | V19: 12 | W19: 170 cr
U20: Pre-Professional Practice
B21: 38 | C21: 6 | D21: 34 | E21: 39 | F21: 6 | G21: 27 | H21: 40 | I21: 6 | J21: 26,35 | K21: 41 | L21: 6 | N21: 42 | O21: 6 | P21: 150 cr
A22: 7 | B22: Algorithms and Competitive Programming | E22: Sistemas Embebidos | H22: Web Technologies | K22: Concentración Tecnológica | N22: Pensamiento de Diseño Aplicado a Ingeniería
B24: 43 | C24: 9 | D24: 20,38,40 | E24: 44 | F24: 6 | G24: 40 | H24: 45 | I24: 6 | J24: 20,27 | K24: 46 | L24: 6 | M24: 40 | R24: 47 | S24: 3 | T24: -
A25: 8 | B25: Proyecto de Desarrollo de Software | E25: Aplicaciones Móviles | H25: Artificial Intelligence | K25: Introducción a la Ingeniería de Software | R25: Opt. Arte y Lit./Hist. y Pens. Cont.
B27: # | C27: Cr | D27: Req.
B28: Nombre Curso

Sheet ICC Tit
A2: Sem | B2: 48 | C2: 6 | D2: 43 | E2: 49 | F2: 6 | G2: 43 | H2: 50 | I2: 6 | J2: 43 | K2: 51 | L2: 6 | M2: 43 | N2: 52 | O2: 6
A3: 1 | B3: Software Design | E3: User Experience Design | H3: Diseño de Software Verificable | K3: Almacenamiento y Procesamiento Masivo de Datos | N3: Electivo Especialidad
B5: 53 | C5: 6 | D5: 43 | E5: 54 | F5: 6 | G5: 48 | H5: 55 | I5: 4 | J5: 276 cr | K5: 56 | L5: 6 | N5: 57 | O5: 6 | Q5: 58 | R5: 2 | S5: 270 cr
A6: 2 | B6: Gestión de Proyectos de Software | E6: Software Architecture | H6: Proyecto Titulo 1 | K6: Electivo Especialidad | N6: Electivo Especialidad | Q6: Seminario Ética Profesional
U7: 59 | V7: 12 | W7: 282 cr
U8: Professional Practice
B9: 60 | C9: 6 | D9: 53 | E9: 61 | F9: 6 | H9: 62 | I9: 18 | J9: 55
A10: 3 | B10: Emprendimiento e Innovación en Software | E10: Electivo Especialidad | H10: Proyecto Titulo 2
B12: # | C12: Cr | D12: Req.
B13: Nombre Curso

Sheet ICA Malla
B2: Año 1 | J2: Año 2 | R2: Año 3 | Z2: Año 4 | AI2: Año 5 | AQ2: Año 6
B3: 1 | F3: 2 | J3: 1 | N3: 2 | R3: 1 | V3: 2 | Z3: 1 | AD3: 2 | AI3: 1 | AM3: 2 | AQ3: 1
A4: Curso 1 | B4: 1 | C4: 10 | D4: - | E4: - | F4: 8 | G4: 6 | H4: - | I4: 1,4,3 | J4: 14 | K4: 6 | L4: - | M4: 3,8,9 | N4: 20 | O4: 6 | P4: - | Q4: 15 | R4: 26 | S4: 6 | U4: 3,15 | V4: 32 | W4: 6 | Y4: 14,26 | Z4: 38 | AA4: 6 | AB4: Ia | AC4: 26,33 | AD4: 43 | AE4: 9 | AF4: Ec | AG4: 35,38,39 | AI4: 48 | AJ4: 6 | AK4: Ec | AL4: 46 | AM4: 53 | AN4: 6 | AO4: Ic(Ob) | AP4: 52 | AQ4: 60 | AR4: 6 | AS4: Ob | AT4: 50,54
B5: Álgebra e Introducción al Cálculo | F5: Álgebra Lineal | J5: Ecuaciones Diferenciales | N5: Probabilidades y Estadística | R5: Metodos Numéricos | V5: Transferencia de Masa | Z5: Balances de Materia y Energía | AD5: Diseño y Optimización de Procesos Industriales | AI5: Gestión Residuos Sólidos y Remediación de Suelos | AM5: Wastewater Treatment | AQ5: Gestión Ambiental y Producción Limpia
A6: Curso 2 | B6: 2 | C6: 5 | D6: ='Malla base'!D6 -> Ea | E6: - | F6: 9 | G6: 6 | H6: - | I6: 1,4 | J6: 15 | K6: 6 | L6: - | M6: 3,9 | N6: 21 | O6: 6 | P6: ='Malla base'!P6 -> Eb | Q6: 15,16 | R6: 27 | S6: 6 | U6: 22 | V6: 33 | W6: 6 | Y6: 26,27 | Z6: 39 | AA6: 6 | AC6: 26,33 | AD6: 44 | AE6: 6 | AF6: Ib | AG6: 38,39 | AI6: 49 | AJ6: 6 | AK6: Ic(Ob) | AL6: 43 | AM6: 54 | AN6: 6 | AP6: 51 | AQ6: 61 | AR6: 6
B7: Fundamentos de Química | F7: Cálculo I | J7: Cálculo II | N7: Electricidad y Magnetismo | R7: Termotecnia | V7: Transferencia de Calor | Z7: Máquinas de Transformación Física y Química | AD7: Cinética y Diseño de Reactores Químicos | AI7: Air Quality and Environmental Pollution | AM7: Economía Ambiental y de los Recursos Naturales | AQ7: Electivo Especialidad
A8: Curso 3 | B8: 3 | C8: 5 | D8: - | E8: - | F8: 10 | G8: 6 | I8: 1 | J8: 16 | K8: 6 | L8: ='Malla base'!L8 -> Eb | M8: 10 | N8: 22 | O8: 5 | P8: ='Malla base'!P8 -> Eb | Q8: 2,15,16 | R8: 28 | S8: 6 | T8: Ec | U8: 11,22 | V8: 34 | W8: 6 | X8: Ic(Ea) | Y8: 14,23 | Z8: 40 | AA8: 6 | AC8: 34 | AD8: 45 | AE8: 6 | AG8: 20,40 | AI8: 50 | AJ8: 6 | AK8: Oa | AL8: 46 | AM8: 55 | AN8: 4 | AP8: 276 cr | AQ8: 62 | AR8: 18 | AT8: 55
B9: Programación | F9: Introducción a la Mecánica | J9: Mecánica y Ondas | N9: Termodinámica | R9: Microbiología Industrial y Ambiental | V9: Fluid Mechanics | Z9: Hidraúlica | AD9: Hidrología | AI9: Legislación y Evaluación de Impacto Ambiental | AM9: Proyecto de Título 1 | AQ9: Proyecto de Título 2
A10: Curso 4 | B10: 4 | C10: 1 | D10: - | E10: - | F10: 11 | G10: 5 | H10: ='Malla base'!H10 -> Ea | I10: 4 | J10: 17 | K10: 5 | L10: ='Malla base'!L10 -> Ia | M10: 1 | N10: 23 | O10: 6 | P10: - | Q10: 9,16 | R10: 29 | S10: 6 | V10: 35 | W10: 6 | X10: Ec | Y10: 28 | Z10: 41 | AA10: 6 | AD10: 46 | AE10: 6 | AF10: Ib | AG10: 28,38 | AI10: 51 | AJ10: 6 | AK10: Ec,Ob | AL10: 43,44 | AM10: 56 | AN10: 6
B11: Bases para el Estudio de Ingeniería | F11: Biología de los Microorganismos | J11: Fundamentos de Economía | N11: Estática | R11: Concentración Tecnológica | V11: Ecología, Medio Ambiente y Energía | Z11: Concentración Tecnológica | AD11: Ingeniería de Bioprocesos Ambientales | AI11: Evaluación de Proyectos de Ingeniería Ambiental | AM11: Electivo Especialidad
A12: Curso 5 | B12: 5 | C12: 3 | E12: - | N12: 24 | O12: 3 | Q12: 7 | V12: 36 | W12: 6 | Z12: 42 | AA12: 6 | AB12: ='Malla base'!AB12 -> Ib(Ea) | AC12: 150 cr | AI12: 52 | AJ12: 6 | AL12: 45 | AM12: 57 | AN12: 6
B13: Taller de Proyectos de Ingeniería | N13: Ética | V13: Concentración Tecnológica | Z13: Pensamiento de Diseño Aplicado a Ingeniería | AI13: Obras Civiles Sanitarias | AM13: Electivo Especialidad
A14: Curso 6 | B14: 6 | C14: 3 | D14: - | E14: - | F14: 12 | G14: 3 | H14: - | I14: 6 | J14: 18 | K14: 3 | L14: - | M14: 12 | N14: 25 | O14: 4 | P14: - | Q14: - | R14: 30 | S14: 3 | T14: - | U14: 24 | AD14: 47 | AE14: 3 | AF14: - | AG14: - | AM14: 58 | AN14: 2 | AO14: ='Malla base'!AO14 -> Ec,Ia | AP14: 270 cr
B15: Teología I | F15: Teología II | J15: Teología III | N15: Minor | R15: Filosofía de las Ciencias | AD15: Optativo Arte y Literatura/Historia y Pensamiento Contemporáneo | AM15: Seminario Ética Profesional
A16: Curso 7 | B16: 7 | C16: 3 | D16: - | E16: - | F16: 13 | G16: 3 | H16: - | I16: - | J16: 19 | K16: 4 | L16: - | M16: - | R16: 31 | S16: 4 | T16: - | U16: -
B17: Antropología Filosófica | F17: Optativo Arte y Literatura/Historia y Pensamiento Contemporáneo | J17: Minor | R17: Minor
X18: 37 | Y18: 12 | Z18: ='Malla base'!Z18 -> Ic(Ea) | AA18: 170 cr | AO18: 60 | AP18: 12 | AQ18: ='Malla base'!AQ18 -> Ic(Eb, Ob) | AR18: 282 cr
E19: * | F19: APR | X19: Pre-Professional Practice | AO19: Professional Practice
E20: Inglés ALTE 3
B22: # | C22: SCT | D22: HT | E22: Req.
B23: Nombre Curso
B25: Año 1 | J25: Año 2 | R25: Año 3 | Z25: Año 4 | AI25: Año 5 | AQ25: Año 6
B26: =C4+C6+C8+C10+C12+C14+C16+G4+G6+G8+G10+G14+G16 -> 59 | J26: =K4+K6+K8+K10+K14+K16+O4+O6+O8+O10+O12+O14 -> 60 | R26: =S4+S6+S8+S10+S14+S16+W4+W6+W8+W10+W12+Y18 -> 73 | Z26: =AA4+AA6+AA8+AA10+AA12+AA14+AE4+AE6+AE8+AE10+AE14 -> 60 | AI26: =AJ4+AJ6+AJ8+AJ10+AJ12+AN4+AN6+AN8+AN10+AN12+AN14+AP18 -> 72 | AQ26: =AR4+AR6+AR8 -> 30

Sheet ICA Lic
A2: Sem | B2: 1 | C2: 10 | D2: - | E2: 2 | F2: 5 | G2: - | H2: 3 | I2: 5 | J2: - | K2: 4 | L2: 1 | M2: - | N2: 5 | O2: 3 | P2: - | R2: 6 | S2: 3 | T2: - | U2: 7 | V2: 3 | W2: -
