Workbook

Sheet Cursos
E1: Especialidades | L1: Horas semanales | S1: 18 | T1: 30 | W1: =SUM(W3:W143) -> 0
A2: CODIGO | B2: MATERIA | C2: CURSO | D2: TITULO | E2: Plan Común | F2: ICI | G2: IOC | H2: ICE | I2: ICC | J2: ICA | K2: Cocentración | L2: Clases | M2: Ayudantías | N2: Laboratorios o Talleres | O2: Trabajos | P2: Presentaciones | Q2: Lecturas | R2: Estudio | S2: Horas semanales | T2: SCT-Chile | U2: Requisitos | V2: Habilidades Transversales | W2: Secciones Sem 10 | X2: Secciones Sem 20 | Y2: Homologación Plan de Estudios 2016, Plan de Estudios 2022 Sólo cambio de malla | Z2: Homologación Plan de Estudios 2011 Sólo cambio de malla | AA2: Cursos similares del Plan de Estudios 2011 (Lista Cruzada) | AB2: CODIGOS BANNER 2010 | AC2: COINCIDENCIA
A3: ING6100 | B3: ING | C3: 6100 | D3: Requisito Inglés ALTE 3 | E3: 0 | F3: 0 | G3: 0 | H3: 0 | I3: 0 | J3: 0 | T3: =ROUND(S3*S$1/T$1,0) -> 0 | AA3: NA | AB3: 0 | AC3: SI
A4: ING1100 | B4: ING | C4: 1100 | D4: Álgebra e Introducción al Cálculo | E4: 1 | F4: 1 | G4: 1 | H4: 1 | I4: 1 | J4: 1 | L4: 8 | M4: 4 | R4: 5 | S4: =SUM(L4:R4) -> 17 | T4: =ROUND(S4*S$1/T$1,0) -> 10 | W4: ✔ | X4: ✔ | Z4: Álgebra (7) y Geometría e Introducción al Cálculo (7) | AA4: Álgebra y Geometría e Introducción al Cálculo | AB4: no disponible | AC4: NO
A5: ING1106 | B5: ING | C5: 1106 | D5: Antropología Filosófica | E5: 1 | F5: 1 | G5: 1 | H5: 1 | I5: 1 | J5: 1 | L5: 2 | Q5: 2 | R5: 1 | S5: =SUM(L5:R5) -> 5 | T5: =ROUND(S5*S$1/T$1,0) -> 3 | W5: ✔ | X5: ✔ | Z5: Antropología Filosófica (3) | AA5: Antropología Filosófica | AB5: no disponible | AC5: NO
A6: ING1400 | B6: ING | C6: 1400 | D6: Bases para el Estudio de Ingeniería | E6: 1 | F6: 1 | G6: 1 | H6: 1 | I6: 1 | J6: 1 | L6: 10 | R6: 10 | S6: =SUM(L6:R6) -> 20 | T6: =ROUND(S6/#REF!,0) -> #REF! | W6: ✔ | Z6: Álgebra (7) o Geometría e Introducción al Cálculo (7) | AA6: NA | AB6: no disponible | AC6: NO
A7: ING1102 | B7: ING | C7: 1102 | D7: Fundamentos de Química | E7: 1 | F7: 1 | G7: 1 | H7: 1 | I7: 1 | J7: 1 | L7: 3 | M7: 2 | N7: 2 | R7: 2 | S7: =SUM(L7:R7) -> 9 | T7: =ROUND(S7*S$1/T$1,0) -> 5 | V7: Ea | W7: ✔ | X7: ✔ | Z7: Química General (7) | AA7: Química General (7) | AB7: 5 | AC7: SI
A8: ING1103 | B8: ING | C8: 1103 | D8: Programación | E8: 1 | F8: 1 | G8: 1 | H8: 1 | I8: 1 | J8: 1 | L8: 2 | N8: 4 | R8: 3 | S8: =SUM(L8:R8) -> 9 | T8: =ROUND(S8*S$1/T$1,0) -> 5 | W8: ✔ | X8: ✔ | Z8: Introducción a la Computación (6) | AA8: Introducción a la Computación (6) | AB8: 5 | AC8: SI
A9: ING1105 | B9: ING | C9: 1105 | D9: Taller de Proyectos de Ingeniería | E9: 1 | F9: 1 | G9: 1 | H9: 1 | I9: 1 | J9: 1 | N9: 4 | O9: 1 | S9: =SUM(L9:R9) -> 5 | T9: =ROUND(S9*S$1/T$1,0) -> 3 | W9: ✔ | Z9: Introducción a la Ingeniería (4) | AA9: Introducción a la Ingeniería (4) | AB9: 3 | AC9: NO
A10: ING1201 | B10: ING | C10: 1201 | D10: Álgebra Lineal | E10: 2 | F10: 2 | G10: 2 | H10: 2 | I10: 2 | J10: 2 | L10: 4 | M10: 2 | N10: 1 | R10: 3 | S10: =SUM(L10:R10) -> 10 | T10: =ROUND(S10*S$1/T$1,0) -> 6 | U10: Bases para el Estudio de Ingeniería, Álgebra e Introducción al Cálculo, Programación (p) | W10: ✔ | X10: ✔ | Z10: Álgebra Lineal (6) | AA10: Álgebra Lineal | AB10: 6 | AC10: SI
A11: ING1204 | B11: ING | C11: 1204 | D11: Biología de los Microorganismos | E11: 2 | F11: 2 | G11: 2 | H11: 2 | I11: 2 | J11: 2 | L11: 3 | N11: 1 | O11: 1 | P11: 1 | Q11: 1 | R11: 2 | S11: =SUM(L11:R11) -> 9 | T11: =ROUND(S11*S$1/T$1,0) -> 5 | U11: Bases para el Estudio de Ingeniería (p) | V11: Ea | W11: ✔ | X11: ✔ | AA11: NA | AB11: 0 | AC11: NO
A12: ING1202 | B12: ING | C12: 1202 | D12: Cálculo I | E12: 2 | F12: 2 | G12: 2 | H12: 2 | I12: 2 | J12: 2 | L12: 4 | M12: 2 | R12: 4 | S12: =SUM(L12:R12) -> 10 | T12: =ROUND(S12*S$1/T$1,0) -> 6 | U12: Bases para el Estudio de Ingeniería, Álgebra e Introducción al Cálculo | W12: ✔ | X12: ✔ | Z12: Cálculo I (6) | AA12: Cálculo I (6) | AB12: 6 | AC12: SI
A13: ING1203 | B13: ING | C13: 1203 | D13: Introducción a la Mecánica | E13: 2 | F13: 2 | G13: 2 | H13: 2 | I13: 2 | J13: 2 | L13: 4 | M13: 2 | N13: 1 | R13: 3 | S13: =SUM(L13:R13) -> 10 | T13: =ROUND(S13*S$1/T$1,0) -> 6 | U13: Álgebra e Introducción al Cálculo | W13: ✔ | X13: ✔ | Z13: Física General I (7) | AA13: Física General I (7) | AB13: 6 | AC13: SI
A14: ING2102 | B14: ING | C14: 2102 | D14: Cálculo II | E14: 3 | F14: 3 | G14: 3 | H14: 3 | I14: 3 | J14: 3 | L14: 4 | M14: 2 | R14: 4 | S14: =SUM(L14:R14) -> 10 | T14: =ROUND(S14*S$1/T$1,0) -> 6 | U14: Programación, Cálculo I | W14: ✔ | X14: ✔ | Z14: Cálculo II (6) | AA14: Cálculo II (6) | AB14: 6 | AC14: SI
A15: ING2101 | B15: ING | C15: 2101 | D15: Ecuaciones Diferenciales | E15: 3 | F15: 3 | G15: 3 | H15: 3 | I15: 3 | J15: 3 | L15: 3 | M15: 2 | N15: 1 | R15: 4 | S15: =SUM(L15:R15) -> 10 | T15: =ROUND(S15*S$1/T$1,0) -> 6 | U15: Programación, Álgebra Lineal, Cálculo I | W15: ✔ | X15: ✔ | Z15: Ecuaciones Diferenciales (6) | AA15: Ecuaciones Diferenciales (6) | AB15: 6 | AC15: SI
A16: ING2104 | B16: ING | C16: 2104 | D16: Fundamentos de Economía | E16: 3 | F16: 3 | G16: 3 | H16: 3 | I16: 3 | J16: 3 | L16: 3 | M16: 2 | O16: 2 | R16: 2 | S16: =SUM(L16:R16) -> 9 | T16: =ROUND(S16*S$1/T$1,0) -> 5 | U16: Álgebra e Introducción al Cálculo | V16: Ia | W16: ✔ | X16: ✔ | Z16: Introducción a la Economía (6) | AA16: Introducción a la Economía (6) | AB16: 5 | AC16: SI
A17: ING2103 | B17: ING | C17: 2103 | D17: Mecánica y Ondas | E17: 3 | F17: 3 | G17: 3 | H17: 3 | I17: 3 | J17: 3 | L17: 4 | M17: 2 | N17: 1 | R17: 3 | S17: =SUM(L17:R17) -> 10 | T17: =ROUND(S17*S$1/T$1,0) -> 6 | U17: Introducción a la Mecánica | V17: Eb | W17: ✔ | X17: ✔ | Z17: Física General II (6) | AA17: Física General II (6) | AB17: 6 | AC17: SI
A18: ING2202 | B18: ING | C18: 2202 | D18: Electricidad y Magnetismo | E18: 4 | F18: 4 | G18: 4 | H18: 4 | I18: 4 | J18: 4 | L18: 4 | M18: 2 | N18: 1 | R18: 3 | S18: =SUM(L18:R18) -> 10 | T18: =ROUND(S18*S$1/T$1,0) -> 6 | U18: Cálculo II, Mecánica y Ondas | V18: Eb | W18: ✔ | X18: ✔ | Z18: Electromagnetismo (6) | AA18: Electromagnetismo (6) | AB18: 6 | AC18: SI
A19: ING2204 | B19: ING | C19: 2204 | D19: Estática | E19: 4 | F19: 4 | G19: 4 | H19: 4 | I19: 4 | J19: 4 | L19: 4 | M19: 2 | R19: 4 | S19: =SUM(L19:R19) -> 10 | T19: =ROUND(S19*S$1/T$1,0) -> 6 | U19: Cálculo I, Mecánica y Ondas | W19: ✔ | X19: ✔ | Z19: Mecánica Racional I (6) | AA19: Mecánica Racional I (6) | AB19: 6 | AC19: SI
A20: ING3104 | B20: ING | C20: 3104 | D20: Ética | E20: 4 | F20: 4 | G20: 4 | H20: 4 | I20: 4 | J20: 4 | L20: 2 | Q20: 2 | R20: 1 | S20: =SUM(L20:R20) -> 5 | T20: =ROUND(S20*S$1/T$1,0) -> 3 | U20: Antropología Filosófica | W20: ✔ | X20: ✔ | Z20: Ética (3) | AA20: Ética (3) | AB20: no disponible | AC20: NO
A21: ING2201 | B21: ING | C21: 2201 | D21: Probabilidades y Estadística | E21: 4 | F21: 4 | G21: 4 | H21: 4 | I21: 4 | J21: 4 | L21: 4 | M21: 2 | R21: 4 | S21: =SUM(L21:R21) -> 10 | T21: =ROUND(S21*S$1/T$1,0) -> 6 | U21: Cálculo II | W21: ✔ | X21: ✔ | Z21: Teoría de Probabilidades (6) y Estadística Aplicada (6) | AA21: Teoría de Probabilidades (6) y Estadística Aplicada (6) | AB21: 6 | AC21: SI
A22: ING2203 | B22: ING | C22: 2203 | D22: Termodinámica | E22: 4 | F22: 4 | G22: 4 | H22: 4 | I22: 4 | J22: 4 | L22: 3 | M22: 2 | N22: 1 | R22: 3 | S22: =SUM(L22:R22) -> 9 | T22: =ROUND(S22*S$1/T$1,0) -> 5 | U22: Fundamentos de Química,Cálculo II, Mecánica y Ondas | V22: Eb | W22: ✔ | X22: ✔ | Z22: Termodinámica (6) | AA22: Termodinámica (6) | AB22: 5 | AC22: SI
A23: ICA5120 | B23: ICA | C23: 5120 | D23: Air Quality and Environmental Pollution | J23: 9 | L23: 3 | M23: 0 | N23: 1 | P23: 1 | R23: 5 | S23: =SUM(L23:R23) -> 10 | T23: =ROUND(S23*S$1/T$1,0) -> 6 | U23: Diseño y Optimización de Procesos Industriales | V23: Ic(Oa) | W23: ✔ | Y23: Air Quality and Environmental Pollution (ICA 5102) | AA23: NA | AB23: 6 | AC23: SI
A24: ICE3101 | B24: ICE | C24: 3101 | D24: Análisis de Circuitos | H24: 5 | K24: 5 | L24: 3 | M24: 2 | N24: 1 | R24: 4 | S24: =SUM(L24:R24) -> 10 | T24: =ROUND(S24*S$1/T$1,0) -> 6 | U24: Ecuaciones Diferenciales, Electricidad y Magnetismo | W24: ✔ | Z24: Análisis de Circuitos (6) | AA24: Análisis de Circuitos | AB24: 6 | AC24: SI
A25: ICE3103 | B25: ICE | C25: 3103 | D25: Sistemas Digitales | H25: 5 | K25: 7 | L25: 3 | N25: 2 | O25: 2 | R25: 3 | S25: =SUM(L25:R25) -> 10 | T25: =ROUND(S25*S$1/T$1,0) -> 6 | U25: Algebra Lineal | W25: ✔ | Z25: Sistemas Digitales (5) o Diseño Digital (11) | AA25: Sistemas Digitales (5) o Diseño Digital (11) | AB25: 6 | AC25: SI
A26: ICE3102 | B26: ICE | C26: 3102 | D26: Señales y Sistemas | H26: 5 | L26: 3 | M26: 2 | N26: 1 | R26: 4 | S26: =SUM(L26:R26) -> 10 | T26: =ROUND(S26*S$1/T$1,0) -> 6 | U26: Ecuaciones Diferenciales | V26: Ia | W26: ✔ | AA26: Señales y Sistemas | AB26: 6 | AC26: SI
A27: ICE3201 | B27: ICE | C27: 3201 | D27: Sistemas Electrónicos | H27: 6 | K27: 6 | L27: 3 | M27: 2 | N27: 1 | R27: 4 | S27: =SUM(L27:R27) -> 10 | T27: =ROUND(S27*S$1/T$1,0) -> 6 | U27: Análisis de Circuitos | X27: ✔ | AA27: Sistemas Análogos | AB27: 6 | AC27: SI
A28: ICE3203 | B28: ICE | C28: 3203 | D28: Optical Systems | H28: 6 | L28: 3 | N28: 2 | R28: 5 | S28: =SUM(L28:R28) -> 10 | T28: =ROUND(S28*S$1/T$1,0) -> 6 | U28: Electricidad y Magnetismo | V28: Ic(Eb) | X28: ✔ | AA28: Optica | AB28: 6 | AC28: SI
A29: ICE3202 | B29: ICE | C29: 3202 | D29: Procesamiento de Señales | H29: 6 | L29: 3 | M29: 2 | O29: 2 | R29: 3 | S29: =SUM(L29:R29) -> 10 | T29: =ROUND(S29*S$1/T$1,0) -> 6 | U29: Señales y Sistemas | V29: Ib | X29: ✔ | AA29: Procesamiento digital de señales | AB29: 6 | AC29: SI
A30: ICE3204 | B30: ICE | C30: 3204 | D30: Sistemas Digitales Avanzados | H30: 6 | L30: 3 | N30: 3 | O30: 2 | R30: 2 | S30: =SUM(L30:R30) -> 10 | T30: =ROUND(S30*S$1/T$1,0) -> 6 | U30: Sistemas Digitales, Análisis de Circuitos (concurrente) | X30: ✔ | AA30: Diseño Digital | AB30: 6 | AC30: SI
A31: ICA4130 | B31: ICA | C31: 4130 | D31: Balances de Materia y Energía | J31: 7 | L31: 3 | M31: 2 | Q31: 1 | R31: 4 | S31: =SUM(L31:R31) -> 10 | T31: =ROUND(S31*S$1/T$1,0) -> 6 | U31: Métodos Numéricos, Transferencia de Calor | V31: Ia | W31: ✔ | Y31: Balances de Materia y Energía (ICA 3101) | AA31: NA | AB31: 6 | AC31: SI
A32: ICA4110 | B32: ICA | C32: 4110 | D32: Cinética y Diseño de Reactores Químicos | J32: 8 | L32: 3 | M32: 2 | N32: 2 | Q32: 1 | R32: 3 | S32: =SUM(L32:R32) -> 11 | T32: =ROUND(S32*S$1/T$1,0) -> 7 | U32: Balances de Materia y Energía, Máquinas de Transformación Física y Química | V32: Ib | X32: ✔ | Y32: Cinética y Diseño de Reactores Químicos (ICA4101) | AA32: NA | AB32: 6 | AC32: SI
A33: ICE4104 | B33: ICE | C33: 4104 | D33: Conversión de Energía | H33: 7 | L33: 3 | N33: 2 | O33: 2 | R33: 3 | S33: =SUM(L33:R33) -> 10 | T33: =ROUND(S33*S$1/T$1,0) -> 6 | U33: Análisis de Circuitos, Termodinámica (concurrente) | V33: Ec | W33: ✔ | AA33: Conversión de Energía | AB33: 6 | AC33: SI
A34: ICE4102 | B34: ICE | C34: 4102 | D34: Introducción a las Comunicaciones | H34: 7 | L34: 3 | N34: 1 | O34: 1 | P34: 1 | Q34: 1 | R34: 3 | S34: =SUM(L34:R34) -> 10 | T34: =ROUND(S34*S$1/T$1,0) -> 6 | U34: Procesamiento de Señales, Probabilidades y Estadística | V34: Ib, Ec | W34: ✔ | AA34: Introducción a las Comunicaciones | AB34: 6 | AC34: SI
A35: ICE4101 | B35: ICE | C35: 4101 | D35: Sistemas Electrónicos Avanzados | H35: 7 | L35: 3 | N35: 3 | O35: 2 | R35: 2 | S35: =SUM(L35:R35) -> 10 | T35: =ROUND(S35*S$1/T$1,0) -> 6 | U35: Sistemas Electrónicos, Señales y Sistemas | W35: ✔ | AA35: Diseño Análogo | AB35: 6 | AC35: SI
A36: ICE4204 | B36: ICE | C36: 4204 | D36: Comunicaciones Digitales | H36: 8 | L36: 3 | N36: 2 | R36: 5 | S36: =SUM(L36:R36) -> 10 | T36: =ROUND(S36*S$1/T$1,0) -> 6 | U36: Introducción a las Comunicaciones | X36: ✔ | AA36: Comunicaciones Modernas | AB36: 6 | AC36: SI
A37: ICE4202 | B37: ICE | C37: 4202 | D37: Control Automático | H37: 8 | L37: 3 | N37: 2 | O37: 2 | R37: 3 | S37: =SUM(L37:R37) -> 10 | T37: =ROUND(S37*S$1/T$1,0) -> 6 | U37: Señales y Sistemas, Mecánica y Ondas | V37: Ec | X37: ✔ | AA37: Control Automático | AB37: 6 | AC37: SI
A38: ICE4203 | B38: ICE | C38: 4203 | D38: Potencia Eléctrica | H38: 8 | L38: 3 | M38: 2 | O38: 2 | R38: 3 | S38: =SUM(L38:R38) -> 10 | T38: =ROUND(S38*S$1/T$1,0) -> 6 | U38: Conversión de Energía | V38: Ec | X38: ✔ | AA38: Potencia Eléctrica | AB38: 6 | AC38: SI
A39: ICE4205 | B39: ICE | C39: 4205 | D39: Proyecto de Diseño Eléctrico | H39: 8 | L39: 3 | N39: 3 | O39: 6 | R39: 3 | S39: =SUM(L39:R39) -> 15 | T39: =ROUND(S39*S$1/T$1,0) -> 9 | U39: 200 SCT de Licenciatura | V39: Ib | X39: ✔ | Z39: ICE5201 Diseño y Simulación de Sistemas Eléctricos (PE2016 V1) | AB39: no disponible | AC39: NO
A40: ICE5104 | B40: ICE | C40: 5104 | D40: Electrónica de Potencia | H40: 9 | L40: 3 | N40: 2 | P40: 2 | R40: 3 | S40: =SUM(L40:R40) -> 10 | T40: =ROUND(S40*S$1/T$1,0) -> 6 | U40: Control Automático | W40: ✔ | AB40: no disponible | AC40: NO
...

Sheet Malla base
B2: Año 1 | J2: Año 2 | R2: Año 3 | Z2: Año 4 | AI2: Año 5 | AQ2: Año 6
B3: 1 | F3: 2 | J3: 1 | N3: 2 | R3: 1 | V3: 2 | Z3: 1 | AD3: 2 | AI3: 1 | AM3: 2 | AQ3: 1
A4: Curso 1 | B4: 1 | C4: 10 | D4: - | E4: - | F4: 8 | G4: 6 | H4: - | I4: 1,4,3 | J4: 14 | K4: 6 | L4: - | M4: 3,8,9 | N4: 20 | O4: 6 | P4: - | Q4: 15 | R4: 26 | S4: 6 | V4: 32 | W4: 6 | Z4: 38 | AA4: 6 | AD4: 43 | AE4: 9 | AI4: 48 | AJ4: 6 | AM4: 53 | AN4: 6 | AQ4: 60 | AR4: 6
B5: Álgebra e Introducción al Cálculo | F5: Álgebra Lineal | J5: Ecuaciones Diferenciales | N5: Probabilidades y Estadística | R5: Licenciatura Especialidad | V5: Licenciatura Especialidad | Z5: Licenciatura Especialidad | AD5: Proyecto Licenciatura | AI5: Especialidad | AM5: Especialidad | AQ5: Electivo Especialidad
A6: Curso 2 | B6: 2 | C6: 5 | D6: Ea | E6: - | F6: 9 | G6: 6 | H6: - | I6: 1,4 | J6: 15 | K6: 6 | L6: - | M6: 3.9 | N6: 21 | O6: 6 | P6: Eb | Q6: 15,16 | R6: 27 | S6: 6 | V6: 33 | W6: 6 | Z6: 39 | AA6: 6 | AD6: 44 | AE6: 6 | AI6: 49 | AJ6: 6 | AM6: 54 | AN6: 6 | AQ6: 61 | AR6: 6
B7: Fundamentos de Química | F7: Cálculo I | J7: Cálculo II | N7: Electricidad y Magnetismo | R7: Licenciatura Especialidad | V7: Licenciatura Especialidad | Z7: Licenciatura Especialidad | AD7: Licenciatura Especialidad | AI7: Especialidad | AM7: Especialidad | AQ7: Electivo Especialidad
A8: Curso 3 | B8: 3 | C8: 5 | D8: - | E8: - | F8: 10 | G8: 6 | H8: - | I8: 1 | J8: 16 | K8: 6 | L8: Eb | M8: 10 | N8: 22 | O8: 5 | P8: Eb | Q8: 2,15,16 | R8: 28 | S8: 6 | V8: 34 | W8: 6 | Z8: 40 | AA8: 6 | AD8: 45 | AE8: 6 | AI8: 50 | AJ8: 6 | AM8: 55 | AN8: 4 | AO8: Ec,Ob | AP8: 276 cr | AQ8: 62 | AR8: 18 | AS8: Ec, Ob | AT8: 55
B9: Programación | F9: Introducción a la Mecánica | J9: Mecánica y Ondas | N9: Termodinámica | R9: Licenciatura Especialidad | V9: Licenciatura Especialidad | Z9: Licenciatura Especialidad | AD9: Licenciatura Especialidad | AI9: Especialidad | AM9: Proyecto de Título 1 | AQ9: Proyecto de Título 2
A10: Curso 4 | B10: 4 | C10: 1 | D10: - | E10: - | F10: 11 | G10: 5 | H10: Ea | I10: 4 | J10: 17 | K10: 5 | L10: Ia | M10: 1 | N10: 23 | O10: 6 | P10: - | Q10: 9,16 | R10: 29 | S10: 6 | V10: 35 | W10: 6 | Z10: 41 | AA10: 6 | AD10: 46 | AE10: 6 | AI10: 51 | AJ10: 6 | AM10: 56 | AN10: 6
B11: Bases para el Estudio de Ingeniería | F11: Biología de los Microorganismos | J11: Fundamentos de Economía | N11: Estática | R11: Concentración Tecnológica | V11: Licenciatura Especialidad | Z11: Concentración Tecnológica | AD11: Licenciatura Especialidad | AI11: Mención/Electivo Especialidad | AM11: Mención/Electivo Especialidad
A12: Curso 5 | B12: 5 | C12: 3 | E12: - | N12: 24 | O12: 3 | Q12: 7 | V12: 36 | W12: 6 | Z12: 42 | AA12: 6 | AB12: Ib(Ea) | AC12: 150 cr | AI12: 52 | AJ12: 6 | AM12: 57 | AN12: 6
B13: Taller de Proyectos de Ingeniería | N13: Ética | V13: Concentración Tecnológica | Z13: Pensamiento de Diseño Aplicado a Ingeniería | AI13: Mención/Electivo Especialidad | AM13: Mención/Electivo Especialidad
A14: Curso 6 | B14: 6 | C14: 3 | D14: - | E14: - | F14: 12 | G14: 3 | H14: - | I14: 6 | J14: 18 | K14: 3 | L14: - | M14: 12 | N14: 25 | O14: 4 | P14: - | Q14: - | R14: 30 | S14: 3 | T14: - | U14: 24 | AD14: 47 | AE14: 3 | AF14: - | AG14: - | AM14: 58 | AN14: 2 | AO14: Ec,Ia | AP14: 270cr
B15: Teología I | F15: Teología II | J15: Teología III | N15: Minor | R15: Filosofía de las Ciencias | AD15: Optativo Arte y Literatura/Historia y Pensamiento Contemporáneo | AM15: Seminario Ética Profesional
A16: Curso 7 | B16: 7 | C16: 3 | D16: - | E16: - | F16: 13 | G16: 3 | H16: - | I16: - | J16: 19 | K16: 4 | L16: - | M16: - | R16: 31 | S16: 4 | T16: - | U16: -
B17: Antropología Filosófica | F17: Optativo Arte y Literatura/Historia y Pensamiento Contemporáneo | J17: Minor | R17: Minor
X18: 37 | Y18: 12 | Z18: Ic(Ea) | AA18: 170 cr | AO18: 59 | AP18: 12 | AQ18: Ic(Eb, Ob) | AR18: 282 cr
E19: * | F19: APR | X19: Pre-Professional Practice | AO19: Professional Practice
E20: Inglés ALTE 3
B22: # | C22: SCT | D22: HT | E22: Req.
B23: Nombre Curso

Sheet ICI Malla
B2: Año 1 | J2: Año 2 | R2: Año 3 | Z2: Año 4 | AI2: Año 5 | AQ2: Año 6
B3: 1 | F3: 2 | J3: 1 | N3: 2 | R3: 1 | V3: 2 | Z3: 1 | AD3: 2 | AI3: 1 | AM3: 2 | AQ3: 1
A4: Curso 1 | B4: 1 | C4: 10 | D4: ='Malla base'!D4 -> - | E4: - | F4: 8 | G4: 6 | H4: - | I4: 1,4,3 | J4: 14 | K4: 6 | L4: - | M4: 3,8,9 | N4: 20 | O4: 6 | P4: - | Q4: 15 | R4: 26 | S4: 6 | U4: 15 | V4: 32 | W4: 6 | Y4: 20,26 | Z4: 38 | AA4: 6 | AC4: 27,32 | AD4: 43 | AE4: 9 | AF4: Ec | AG4: 38,40 | AI4: 48 | AJ4: 6 | AL4: 35 | AM4: 53 | AN4: 6 | AO4: Ob | AP4: 43 | AQ4: 60 | AR4: 6
B5: Álgebra e Introducción al Cálculo | F5: Álgebra Lineal | J5: Ecuaciones Diferenciales | N5: Probabilidades y Estadística | R5: Optimización | V5: Modelos Estocásticos | Z5: Simulación | AD5: Diseño y Evaluación de Proyectos Industriales | AI5: Organización Industrial | AM5: Gestión Estratégica | AQ5: Electivo Especialidad
A6: Curso 2 | B6: 2 | C6: 5 | D6: ='Malla base'!D6 -> Ea | E6: - | F6: 9 | G6: 6 | H6: - | I6: 1,4 | J6: 15 | K6: 6 | L6: - | M6: 3,9 | N6: 21 | O6: 6 | P6: ='Malla base'!P6 -> Eb | Q6: 15,16 | R6: 27 | S6: 6 | T6: Ec | U6: 20 | V6: 33 | W6: 6 | Y6: 20,26 | Z6: 39 | AA6: 6 | AB6: Ib | AC6: 27 | AD6: 44 | AE6: 6 | AF6: Ib | AG6: 33,39 | AI6: 49 | AJ6: 6 | AK6: Ic(Ea) | AL6: 39 | AM6: 54 | AN6: 6 | AP6: 43 | AQ6: 61 | AR6: 6
B7: Fundamentos de Química | F7: Cálculo I | J7: Cálculo II | N7: Electricidad y Magnetismo | R7: Métodos Estadísticos para la Gestión | V7: Programación Matemática | Z7: Econometría | AD7: Gestión de Operaciones | AI7: Marketing | AM7: Gestión de Personas y Desarrollo Organizacional | AQ7: Mención
A8: Curso 3 | B8: 3 | C8: 5 | D8: - | E8: - | F8: 10 | G8: 6 | H8: ='Malla base'!H8 -> - | I8: 1 | J8: 16 | K8: 6 | L8: ='Malla base'!L8 -> Eb | M8: 10 | N8: 22 | O8: 5 | P8: ='Malla base'!P8 -> Eb | Q8: 2,15,16 | R8: 28 | S8: 6 | U8: 17 | V8: 34 | W8: 6 | Y8: 3 | Z8: 40 | AA8: 6 | AC8: 28 | AD8: 45 | AE8: 6 | AF8: Ec | AG8: 40 | AI8: 50 | AJ8: 6 | AK8: Ic(Oa) | AL8: 44 | AM8: 55 | AN8: 4 | AO8: Ec,Ob | AP8: 276 cr | AQ8: 62 | AR8: 18 | AS8: Ec, Ob | AT8: 55
B9: Programación | F9: Introducción a la Mecánica | J9: Mecánica y Ondas | N9: Termodinámica | R9: Contabilidad y Estados Financieros | V9: Bases de Datos | Z9: Finanzas I | AD9: Finanzas II | AI9: Logistics | AM9: Proyecto de Título 1 | AQ9: Proyecto de Título 2
A10: Curso 4 | B10: 4 | C10: 1 | D10: - | E10: - | F10: 11 | G10: 5 | H10: ='Malla base'!H10 -> Ea | I10: 4 | J10: 17 | K10: 5 | L10: ='Malla base'!L10 -> Ia | M10: 1 | N10: 23 | O10: 6 | P10: - | Q10: 9,16 | R10: 29 | S10: 6 | V10: 35 | W10: 6 | X10: Ia | Y10: 17 | Z10: 41 | AA10: 6 | AD10: 46 | AE10: 6 | AG10: 17 | AI10: 51 | AJ10: 6 | AM10: 56 | AN10: 6
B11: Bases para el Estudio de Ingeniería | F11: Biología de los Microorganismos | J11: Fundamentos de Economía | N11: Estática | R11: Concentración Tecnológica | V11: Microeconomía | Z11: Concentración Tecnológica | AD11: Macroeconomía | AI11: Mención | AM11: Mención
A12: Curso 5 | B12: 5 | C12: 3 | E12: - | N12: 24 | O12: 3 | Q12: 7 | V12: 36 | W12: 6 | Z12: 42 | AA12: 6 | AB12: Ib(Ea) | AC12: 150 cr | AI12: 52 | AJ12: 6 | AM12: 57 | AN12: 6
B13: Taller de Proyectos de Ingeniería | N13: Ética | V13: Concentración Tecnológica | Z13: Pensamiento de Diseño Aplicado a Ingeniería | AI13: Electivo Especialidad | AM13: Electivo Especialidad
A14: Curso 6 | B14: 6 | C14: 3 | D14: - | E14: - | F14: 12 | G14: 3 | H14: - | I14: 6 | J14: 18 | K14: 3 | L14: - | M14: 12 | N14: 25 | O14: 4 | P14: - | Q14: - | R14: 30 | S14: 3 | T14: - | U14: 24 | AD14: 47 | AE14: 3 | AF14: - | AG14: - | AM14: 58 | AN14: 2 | AO14: Ec | AP14: 270 cr
B15: Teología I | F15: Teología II | J15: Teología III | N15: Minor | R15: Filosofía de las Ciencias | AD15: Optativo Arte y Literatura/Historia y Pensamiento Contemporáneo | AM15: Seminario Ética Profesional
A16: Curso 7 | B16: 7 | C16: 3 | D16: - | E16: - | F16: 13 | G16: 3 | H16: - | I16: - | J16: 19 | K16: 4 | L16: - | M16: - | R16: 31 | S16: 4 | T16: - | U16: -
B17: Antropología Filosófica | F17: Optativo Arte y Literatura/Historia y Pensamiento Contemporáneo | J17: Minor | R17: Minor
X18: 37 | Y18: 12 | Z18: ='Malla base'!Z18 -> Ic(Ea) | AA18: 170 cr | AO18: 59 | AP18: 12 | AQ18: ='Malla base'!AQ18 -> Ic(Eb, Ob) | AR18: 282 cr
E19: * | F19: APR | X19: Pre-Professional Practice | AO19: Professional Practice
E20: Inglés ALTE 3
B22: # | C22: SCT | D22: HT | E22: Req.
B23: Nombre Curso
B24: Año 1 | J24: Año 2 | R24: Año 3 | Z24: Año 4 | AI24: Año 5 | AQ24: Año 6
B25: =C4+C6+C8+C10+C12+C14+C16+G4+G6+G8+G10+G14+G16 -> 59 | J25: =K4+K6+K8+K10+K14+K16+O4+O6+O8+O10+O14+O12 -> 60 | R25: =S4+S6+S8+S10+S14+S16+W4+W6+W8+W10+W12+Y18 -> 73 | Z25: =AA4+AA6+AA8+AA10+AA12+AA14+AE4+AE6+AE8+AE10+AE14 -> 60 | AI25: =AJ4+AJ6+AJ8+AJ10+AJ12+AN4+AN6+AN8+AN10+AN12+AN14+AP18 -> 72 | AQ25: =AR4+AR6+AR8 -> 30

Sheet ICI Tit
A3: Mención Gestión de Operaciones
A5: Sem | B5: 48 | C5: 6 | D5: 35 | E5: 49 | F5: 6 | G5: 39 | H5: 50 | I5: 6 | J5: 44 | K5: 51 | L5: 6 | M5: 39 | N5: 52 | O5: 6
A6: 1 | B6: Organización Industrial | E6: Marketing | H6: Logistics | K6: Series de Tiempo | N6: Electivo Especialidad
B8: 53 | C8: 6 | D8: 43 | E8: 54 | F8: 6 | G8: 43 | H8: 55 | I8: 4 | J8: 276 cr | K8: 56 | L8: 6 | M8: 44 | N8: 57 | O8: 6 | Q8: 58 | R8: 2 | S8: 270 cr
A9: 2 | B9: Gestión Estratégica | E9: Gestión de Personas y Desarrollo Organizacional | H9: Proyecto Titulo 1 | K9: Modelamiento del Transporte | N9: Electivo Especialidad | Q9: Seminario Ética Profesional
U10: 59 | V10: 12 | W10: 282 cr
U11: Professional Practice
B12: 60 | C12: 6 | E12: 61 | F12: 6 | G12: 50 | H12: 62 | I12: 18 | J12: 55
A13: 3 | B13: Electivo Especialidad | E13: Estudio de Casos en Gestión de Operaciones | H13: Proyecto Titulo 2
A15: Mención Ingeniería Financiera
A17: Sem | B17: 48 | C17: 6 | D17: 35 | E17: 49 | F17: 6 | G17: 39 | H17: 50 | I17: 6 | J17: 44 | K17: 51 | L17: 6 | M17: 40 | N17: 52 | O17: 6
A18: 1 | B18: Organización Industrial | E18: Marketing | H18: Logistics | K18: Instituciones Financieras | N18: Electivo Especialidad
B20: 53 | C20: 6 | D20: 43 | E20: 54 | F20: 6 | G20: 43 | H20: 55 | I20: 4 | J20: 276 cr | K20: 56 | L20: 6 | M20: 45 | N20: 57 | O20: 6 | Q20: 58 | R20: 2 | S20: 270 cr
A21: 2 | B21: Gestión Estratégica | E21: Gestión de Personas y Desarrollo Organizacional | H21: Proyecto Titulo 1 | K21: Gestión Financiera | N21: Electivo de Especialidad | Q21: Seminario Ética Profesional
U22: 59 | V22: 12 | W22: 282 cr
U23: Professional Practice
B24: 60 | C24: 6 | E24: 61 | F24: 6 | G24: 45 | H24: 62 | I24: 18 | J24: 55
A25: 3 | B25: Electivo Especialidad | E25: Tópicos de Finanzas | H25: Proyecto Titulo 2
A28: Mención Analítica de Datos
A30: Sem | B30: 48 | C30: 6 | D30: 35 | E30: 49 | F30: 6 | G30: 39 | H30: 50 | I30: 6 | J30: 44 | K30: 51 | L30: 6 | M30: 34, 39 | N30: 52 | O30: 6
A31: 1 | B31: Organización Industrial | E31: Marketing | H31: Logistics | K31: Business Analytics | N31: Electivo Especialidad
B33: 53 | C33: 6 | D33: 43 | E33: 54 | F33: 6 | G33: 43 | H33: 55 | I33: 4 | J33: 276 cr | K33: 56 | L33: 6 | M33: 27, 32, 33 | N33: 57 | O33: 6 | Q33: 58 | R33: 2 | S33: 270 cr
A34: 2 | B34: Gestión Estratégica | E34: Gestión de Personas y Desarrollo Organizacional | H34: Proyecto Titulo 1 | K34: Deep Learning | N34: Electivo de Especialidad | Q34: Seminario Ética Profesional
U35: 59 | V35: 12 | W35: 282 cr
U36: Professional Practice
B37: 60 | C37: 6 | E37: 61 | F37: 6 | G37: 35,38 | H37: 62 | I37: 18 | J37: 55
A38: 3 | B38: Electivo Especialidad | E38: Tecnologías para la Transformación Digital | H38: Proyecto Titulo 2

Sheet IOC Malla
B2: Año 1 | J2: Año 2 | R2: Año 3 | Z2: Año 4 | AI2: Año 5 | AQ2: Año 6
B3: 1 | F3: 2 | J3: 1 | N3: 2 | R3: 1 | V3: 2 | Z3: 1 | AD3: 2 | AI3: 1 | AM3: 2 | AQ3: 1
A4: Curso 1 | B4: 1 | C4: 10 | D4: - | E4: - | F4: 8 | G4: 6 | H4: - | I4: 1,4,3 | J4: 14 | K4: 6 | L4: - | M4: 3,8,9 | N4: 20 | O4: 6 | P4: - | Q4: 15 | R4: 26 | S4: 6 | T4: Ib | U4: 14,23 | V4: 32 | W4: 6 | X4: Ib | Y4: 26 | Z4: 38 | AA4: 6 | AB4: Ec, Ib | AC4: 32 | AD4: 43 | AE4: 9 | AF4: Ec | AG4: 28,38,40 | AI4: 48 | AJ4: 6 | AK4: Ic(Oa) | AL4: 228 cr | AM4: 53 | AN4: 6 | AQ4: 60 | AR4: 6
B5: Álgebra e Introducción al Cálculo | F5: Álgebra Lineal | J5: Ecuaciones Diferenciales | N5: Probabilidades y Estadística | R5: Mecánica de Materiales | V5: Análisis Estructural | Z5: Hormigón Armado | AD5: Métodos Computacionales en Obras Civiles | AI5: Dynamics of Structures | AM5: Electivo Especialidad | AQ5: Electivo Especialidad
A6: Curso 2 | B6: 2 | C6: 5 | D6: ='[1]Malla base'!D6 -> Ea | E6: - | F6: 9 | G6: 6 | H6: - | I6: 1,4 | J6: 15 | K6: 6 | L6: - | M6: 3,9 | N6: 21 | O6: 6 | P6: ='[1]Malla base'!P6 -> Eb | Q6: 15,16 | R6: 27 | S6: 6 | U6: 15 | V6: 33 | W6: 6 | Y6: 9 | Z6: 39 | AA6: 6 | AC6: 26 | AD6: 44 | AE6: 6 | AG6: 33,35 | AI6: 49 | AJ6: 6 | AL6: 228 cr | AM6: 54 | AN6: 6 | AO6: Ia,Ec | AP6: 240 cr | AQ6: 61 | AR6: 6 | AS6: Ec,Ob
B7: Fundamentos de Química | F7: Cálculo I | J7: Cálculo II | N7: Electricidad y Magnetismo | R7: Optimización | V7: Topografía Aplicada | Z7: Introducción a la Geomecánica | AD7: Métodos y Técnicas de Construcción | AI7: Diseño en Acero | AM7: Tecnología del Hormigón | AQ7: Proyecto Civil
A8: Curso 3 | B8: 3 | C8: 5 | D8: - | E8: - | F8: 10 | G8: 6 | I8: 1 | J8: 16 | K8: 6 | L8: ='[1]Malla base'!L8 -> Eb | M8: 10 | N8: 22 | O8: 5 | P8: ='[1]Malla base'!P8 -> Eb | Q8: 2,15,16 | R8: 28 | S8: 6 | U8: 3,15 | V8: 34 | W8: 6 | X8: Ic(Ea) | Y8: 14,23 | Z8: 40 | AA8: 6 | AC8: 34 | AD8: 45 | AE8: 6 | AG8: 20,40 | AI8: 50 | AJ8: 6 | AK8: Ec,Ob | AL8: 43,44 | AM8: 55 | AN8: 4 | AO8: Ec,Ob | AP8: 276 cr | AQ8: 62 | AR8: 18 | AS8: Ec,Ob | AT8: 55
B9: Programación | F9: Introducción a la Mecánica | J9: Mecánica y Ondas | N9: Termodinámica | R9: Métodos Numéricos | V9: Fluid Mechanics | Z9: Hidráulica | AD9: Hidrología | AI9: Evaluación de Proyectos de Ingeniería | AM9: Proyecto de Título 1 | AQ9: Proyecto de Título 2
A10: Curso 4 | B10: 4 | C10: 1 | D10: - | E10: - | F10: 11 | G10: 5 | H10: ='[1]Malla base'!H10 -> Ea | I10: 4 | J10: 17 | K10: 5 | L10: ='[1]Malla base'!L10 -> Ia | M10: 1 | N10: 23 | O10: 6 | P10: - | Q10: 9,16 | R10: 29 | S10: 6 | V10: 35 | W10: 6 | X10: Ib | Y10: 2 | Z10: 41 | AA10: 6 | AD10: 46 | AE10: 6 | AG10: 17,20 | AI10: 51 | AJ10: 6 | AM10: 56 | AN10: 6
B11: Bases para el Estudio de Ingeniería | F11: Biología de los Microorganismos | J11: Fundamentos de Economía | N11: Estática | R11: Concentración Tecnológica | V11: Materiales de Construcción | Z11: Concentración Tecnológica | AD11: Sistemas de Transporte | AI11: Mención | AM11: Mención
A12: Curso 5 | B12: 5 | C12: 3 | E12: - | N12: 24 | O12: 3 | Q12: 7 | V12: 36 | W12: 6 | Z12: 42 | AA12: 6 | AB12: Ib(Ea) | AC12: 150 cr | AI12: 52 | AJ12: 6 | AM12: 57 | AN12: 6
B13: Taller de Proyectos de Ingeniería | N13: Ética | V13: Concentración Tecnológica | Z13: Pensamiento de Diseño Aplicado a Ingeniería | AI13: Mención | AM13: Mención
A14: Curso 6 | B14: 6 | C14: 3 | D14: - | E14: - | F14: 12 | G14: 3 | H14: - | I14: 6 | J14: 18 | K14: 3 | L14: - | M14: 12 | N14: 25 | O14: 4 | P14: - | Q14: - | R14: 30 | S14: 3 | T14: - | U14: 24 | AD14: 47 | AE14: 3 | AF14: - | AG14: - | AM14: 58 | AN14: 2 | AO14: ='[1]Malla base'!AO14 -> Ec,Ia | AP14: 270 cr
B15: Teología I | F15: Teología II | J15: Teología III | N15: Minor | R15: Filosofía de las Ciencias | AD15: Optativo Arte y Literatura/Historia y Pensamiento Contemporáneo | AM15: Seminario Ética Profesional
A16: Curso 7 | B16: 7 | C16: 3 | D16: - | E16: - | F16: 13 | G16: 3 | H16: - | I16: - | J16: 19 | K16: 4 | L16: - | M16: - | R16: 31 | S16: 4 | T16: - | U16: -
B17: Antropología Filosófica | F17: Optativo Arte y Literatura/Historia y Pensamiento Contemporáneo | J17: Minor | R17: Minor
X18: 37 | Y18: 12 | Z18: ='[1]Malla base'!Z18 -> Ic(Ea) | AA18: 170 cr | AO18: 59 | AP18: 12 | AQ18: ='[1]Malla base'!AQ18 -> Ic(Eb, Ob) | AR18: 282 cr
E19: * | F19: APR | X19: Pre-Professional Practice | AO19: Professional Practice
E20: Inglés ALTE 3
B22: # | C22: SCT | D22: HT | E22: Req.
B23: Nombre Curso
B25: Año 1 | J25: Año 2 | R25: Año 3 | Z25: Año 4 | AI25: Año 5 | AQ25: Año 6
B26: =C4+C6+C8+C10+C12+C14+C16+G4+G6+G8+G10+G14+G16 -> 59 | J26: =K4+K6+K8+K10+K14+K16+O4+O6+O8+O10+O12+O14 -> 60 | R26: =S4+S6+S8+S10+S14+S16+W4+W6+W8+W10+W12+Y18 -> 73 | Z26: =AA4+AA6+AA8+AA10+AA12+AA14+AE4+AE6+AE8+AE10+AE14 -> 60 | AI26: =AJ4+AJ6+AJ8+AJ10+AJ12+AN4+AN6+AN8+AN10+AN12+AN14+AP18 -> 72 | AQ26: =AR4+AR6+AR8 -> 30

Sheet IOC Tit
A2: Mención Estructuras
A4: Sem | B4: 48 | C4: 6 | D4: 228 cr | E4: 49 | F4: 6 | G4: 228 cr | H4: 50 | I4: 6 | J4: 43,44 | K4: 51 | L4: 6 | M4: 228 cr | N4: 52 | O4: 6 | P4: 32,43
A5: 1 | B5: Dynamics of Structures | E5: Diseño en Acero | H5: Evaluación de Proyectos de Ingeniería | K5: Fundaciones | N5: Finite Elements
B7: 53 | C7: 6 | E7: 54 | F7: 6 | G7: 240 cr | H7: 55 | I7: 4 | J7: 276 cr | K7: 56 | L7: 6 | M7: 240 cr | N7: 57 | O7: 6 | P7: 38,48 | Q7: 58 | R7: 2 | S7: 270 cr
A8: 2 | B8: Electivo Especialidad | E8: Tecnología del Hormigón | H8: Proyecto Titulo 1 | K8: Hormigón Armado Avanzado | N8: Diseño Sismorresistente | Q8: Seminario Ética Profesional
U9: 59 | V9: 12 | W9: 282 cr
U10: Professional Practice
B11: 60 | C11: 6 | E11: 61 | F11: 6 | G11: 57 | H11: 62 | I11: 18 | J11: 55
A12: 3 | B12: Electivo Especialidad | E12: Proyecto Civil (Mención Estructuras) | H12: Proyecto Titulo 2
A14: Mención Desarrollo de Proyectos de Infraestructura
A16: Sem | B16: 48 | C16: 6 | D16: 228 cr | E16: 49 | F16: 6 | G16: 228 cr | H16: 50 | I16: 6 | J16: 43,44 | K16: 51 | L16: 6 | M16: 228 cr | N16: 52 | O16: 6 | P16: 45
A17: 1 | B17: Dynamics of Structures | E17: Diseño en Acero | H17: Evaluación de Proyectos de Ingeniería | K17: Cost Engineering | N17: Hidráulica Urbana
B19: 53 | C19: 6 | E19: 54 | F19: 6 | G19: 240 cr | H19: 55 | I19: 4 | J19: 276 cr | K19: 56 | L19: 6 | M19: 51 | N19: 57 | O19: 6 | P19: 44,46 | Q19: 58 | R19: 2 | S19: 270 cr
A20: 2 | B20: Electivo Especialidad | E20: Tecnología del Hormigón | H20: Proyecto Titulo 1 | K20: Administración y Control de Proyectos | N20: Ingeniería Vial | Q20: Seminario Ética Profesional
U21: 59 | V21: 12 | W21: 282 cr
U22: Professional Practice
B23: 60 | C23: 6 | E23: 61 | F23: 6 | G23: 56 | H23: 62 | I23: 18 | J23: 55
A24: 3 | B24: Electivo Especialidad | E24: Proyecto Civil (Mención DPI) | H24: Proyecto Titulo 2

Sheet ICE Malla
B2: Año 1 | J2: Año 2 | R2: Año 3 | Z2: Año 4 | AI2: Año 5 | AQ2: Año 6
B3: 1 | F3: 2 | J3: 1 | N3: 2 | R3: 1 | V3: 2 | Z3: 1 | AD3: 2 | AI3: 1 | AM3: 2 | AQ3: 1
A4: Curso 1 | B4: 1 | C4: 10 | D4: - | E4: - | F4: 8 | G4: 6 | H4: - | I4: 1,4,3 | J4: 14 | K4: 6 | L4: - | M4: 3,8,9 | N4: 20 | O4: 6 | P4: - | Q4: 15 | R4: 26 | S4: 6 | U4: 14,21 | V4: 32 | W4: 6 | Y4: 26 | Z4: 38 | AA4: 6 | AC4: 27,32 | AD4: 43 | AE4: 9 | AF4: Ib | AG4: 200 cr. | AI4: 48 | AJ4: 6 | AL4: 44 | AM4: 53 | AN4: 6 | AO4: Ic(Oa) | AP4: 20,27 | AQ4: 60 | AR4: 6
B5: Álgebra e Introducción al Cálculo | F5: Álgebra Lineal | J5: Ecuaciones Diferenciales | N5: Probabilidades y Estadística | R5: Análisis de Circuitos | V5: Sistemas Electrónicos | Z5: Sistemas Electrónicos Avanzados | AD5: Proyecto de Diseño Eléctrico | AI5: Electrónica de Potencia | AM5: Artificial Intelligence | AQ5: Electivo
A6: Curso 2 | B6: 2 | C6: 5 | D6: ='Malla base'!D6 -> Ea | E6: - | F6: 9 | G6: 6 | H6: - | I6: 1,4 | J6: 15 | K6: 6 | L6: - | M6: 3,9 | N6: 21 | O6: 6 | P6: ='Malla base'!P6 -> Eb | Q6: 15,16 | R6: 27 | S6: 6 | T6: Ia | U6: 14 | V6: 33 | W6: 6 | X6: Ib | Y6: 27 | Z6: 39 | AA6: 6 | AB6: Ec,Ib | AC6: 20,33 | AD6: 44 | AE6: 6 | AF6: Ec | AG6: 16,27 | AI6: 49 | AJ6: 6 | AK6: Ec, Ob | AL6: 45 | AM6: 54 | AN6: 6 | AP6: 39 | AQ6: 61 | AR6: 6
B7: Fundamentos de Química | F7: Cálculo I | J7: Cálculo II | N7: Electricidad y Magnetismo | R7: Señales y Sistemas | V7: Procesamiento de Señales | Z7: Introducción a las Comunicaciones | AD7: Control Automático | AI7: Sistemas de Potencia | AM7: Redes de Comunicación | AQ7: Electivo
A8: Curso 3 | B8: 3 | C8: 5 | D8: - | E8: - | F8: 10 | G8: 6 | H8: - | I8: 1 | J8: 16 | K8: 6 | L8: ='Malla base'!L8 -> Eb | M8: 10 | N8: 22 | O8: 5 | P8: ='Malla base'!P8 -> Eb | Q8: 2,15,16 | R8: 28 | S8: 6 | U8: 8 | V8: 34 | W8: 6 | X8: Ic(Ec) | Y8: 21 | Z8: 40 | AA8: 6 | AB8: Ec | AC8: 22,26 | AD8: 45 | AE8: 6 | AF8: Ec | AG8: 40 | AI8: 50 | AJ8: 6 | AK8: Ec,Ob | AL8: 34,40 | AM8: 55 | AN8: 4 | AO8: Ec,Ob | AP8: 276 cr | AQ8: 62 | AR8: 18 | AS8: Ec,Ob | AT8: 55
B9: Programación | F9: Introducción a la Mecánica | J9: Mecánica y Ondas | N9: Termodinámica | R9: Sistemas Digitales | V9: Optical Systems | Z9: Conversión de Energía | AD9: Potencia Eléctrica | AI9: Fundamentos de Energías Renovables | AM9: Proyecto de Título 1 | AQ9: Proyecto de Título 2
A10: Curso 4 | B10: 4 | C10: 1 | D10: - | E10: - | F10: 11 | G10: 5 | H10: ='Malla base'!H10 -> Ea | I10: 4 | J10: 17 | K10: 5 | L10: ='ICI Malla'!L10 -> Ia | M10: 1 | N10: 23 | O10: 6 | P10: - | Q10: 9,16 | R10: 29 | S10: 6 | V10: 35 | W10: 6 | Y10: 26,28 | Z10: 41 | AA10: 6 | AD10: 46 | AE10: 6 | AG10: 39 | AI10: 51 | AJ10: 6 | AL10: 45 | AM10: 56 | AN10: 6 | AP10: 49
B11: Bases para el Estudio de Ingeniería | F11: Biología de los Microorganismos | J11: Fundamentos de Economía | N11: Estática | R11: Concentración Tecnológica | V11: Sistemas Digitales Avanzados | Z11: Concentración Tecnológica | AD11: Comunicaciones Digitales | AI11: Mercados Eléctricos | AM11: Protecciones Eléctricas
A12: Curso 5 | B12: 5 | C12: 3 | E12: - | N12: 24 | O12: 3 | Q12: 7 | V12: 36 | W12: 6 | Z12: 42 | AA12: 6 | AB12: Ib(Ea) | AC12: 150 cr | AI12: 52 | AJ12: 6 | AM12: 57 | AN12: 6
B13: Taller de Proyectos de Ingeniería | N13: Ética | V13: Concentración Tecnológica | Z13: Pensamiento de Diseño Aplicado a Ingeniería | AI13: Electivo | AM13: Electivo
A14: Curso 6 | B14: 6 | C14: 3 | D14: - | E14: - | F14: 12 | G14: 3 | H14: - | I14: 6 | J14: 18 | K14: 3 | L14: - | M14: 12 | N14: 25 | O14: 4 | P14: - | Q14: - | R14: 30 | S14: 3 | T14: - | U14: 24 | AD14: 47 | AE14: 3 | AF14: - | AG14: - | AM14: 58 | AN14: 2 | AO14: Ec | AP14: 270 cr
B15: Teología I | F15: Teología II | J15: Teología III | N15: Minor | R15: Filosofía de las Ciencias | AD15: Optativo Arte y Literatura/Historia y Pensamiento Contemporáneo | AM15: Seminario Ética Profesional
A16: Curso 7 | B16: 7 | C16: 3 | D16: - | E16: - | F16: 13 | G16: 3 | H16: - | I16: - | J16: 19 | K16: 4 | L16: - | M16: - | R16: 31 | S16: 4 | T16: - | U16: -
B17: Antropología Filosófica | F17: Optativo Arte y Literatura/Historia y Pensamiento Contemporáneo | J17: Minor | R17: Minor
X18: 37 | Y18: 12 | Z18: ='Malla base'!Z18 -> Ic(Ea) | AA18: 170 cr | AO18: 59 | AP18: 12 | AQ18: ='Malla base'!AQ18 -> Ic(Eb, Ob) | AR18: 282 cr
E19: * | F19: APR | X19: Pre-Professional Practice | AO19: Professional Practice
E20: Inglés ALTE 3
B22: # | C22: SCT | D22: HT | E22: Req.
B23: Nombre Curso
B26: Año 1 | J26: Año 2 | R26: Año 3 | Z26: Año 4 | AI26: Año 5 | AQ26: Año 6
B27: =C4+C6+C8+C10+C12+C14+C16+G4+G6+G8+G10+G14+G16 -> 59 | J27: =K4+K6+K8+K10+K14+K16+O4+O6+O8+O10+O12+O14 -> 60 | R27: 61 | Z27: =AA4+AA6+AA8+AA10+AA12+AA14+AE4+AE6+AE8+AE10+AE14 -> 60 | AI27: =AJ4+AJ6+AJ8+AJ10+AJ12+AN4+AN6+AN8+AN10+AN12+AN14+AP18 -> 72 | AQ27: =AR4+AR6+AR8 -> 30

Sheet ICC Malla
B2: Año 1 | J2: Año 2 | R2: Año 3 | Z2: Año 4 | AI2: Año 5 | AQ2: Año 6
B3: 1 | F3: 2 | J3: 1 | N3: 2 | R3: 1 | V3: 2 | Z3: 1 | AD3: 2 | AI3: 1 | AM3: 2 | AQ3: 1
A4: Curso 1 | B4: 1 | C4: 10 | D4: - | E4: - | F4: 8 | G4: 6 | H4: - | I4: 1,4,3 | J4: 14 | K4: 6 | L4: - | M4: 3,8,9 | N4: 20 | O4: 6 | P4: - | Q4: 15 | R4: 26 | S4: 6 | T4: - | U4: 3 | V4: 32 | W4: 6 | X4: - | Y4: 27 | Z4: 38 | AA4: 6 | AB4: Ic | AC4: 34 | AD4: 43 | AE4: 9 | AF4: Oa | AG4: 20,35,40 | AI4: 48 | AJ4: 6 | AK4: Ic | AL4: 46 | AM4: 53 | AN4: 6 | AP4: 46 | AQ4: 60 | AR4: 6 | AS4: Ec, Ob | AT4: 43,53
B5: Álgebra e Introducción al Cálculo | F5: Álgebra Lineal | J5: Ecuaciones Diferenciales | N5: Probabilidades y Estadística | R5: Paradigmas de Programación | V5: Sistemas Operativos y Redes | Z5: Algorithms and Competitive Programming | AD5: Proyecto de Desarrollo de Software | AI5: Software Design | AM5: Gestión de Proyectos de Software | AQ5: Emprendimiento e Innovación en Software
A6: Curso 2 | B6: 2 | C6: 5 | D6: ='[2]Malla base'!D6 -> Ea | E6: - | F6: 9 | G6: 6 | H6: - | I6: 1,4 | J6: 15 | K6: 6 | L6: - | M6: 3,9 | N6: 21 | O6: 6 | P6: ='[2]Malla base'!P6 -> Eb | Q6: 15,16 | R6: 27 | S6: 6 | T6: - | U6: 3 | V6: 33 | W6: 6 | X6: - | Y6: 21 | Z6: 39 | AA6: 6 | AB6: Eb | AC6: 32,35 | AD6: 44 | AE6: 6 | AF6: Ia | AG6: 35 | AI6: 49 | AJ6: 6 | AK6: Ic(Eb) | AL6: 43 | AM6: 54 | AN6: 6 | AO6: Ic(Ob) | AP6: 48,39,45 | AQ6: 61 | AR6: 6
B7: Fundamentos de Química | F7: Cálculo I | J7: Cálculo II | N7: Electricidad y Magnetismo | R7: Programación de Bajo Nivel | V7: Arquitectura de Computadores | Z7: Fundamentos de Ciberseguridad | AD7: Aplicaciones Móviles | AI7: User Experience Design | AM7: Software Architecture | AQ7: Electivo Especialidad
A8: Curso 3 | B8: 3 | C8: 5 | D8: - | E8: - | F8: 10 | G8: 6 | H8: - | I8: 1 | J8: 16 | K8: 6 | L8: ='[2]Malla base'!L8 -> Eb | M8: 10 | N8: 22 | O8: 5 | P8: ='[2]Malla base'!P8 -> Eb | Q8: 2,15,16 | R8: 28 | S8: 6 | U8: 3 | V8: 34 | W8: 6 | X8: Ib | Y8: 27 | Z8: 40 | AA8: 6 | AB8: Ic(Oa) | AC8: 20,27 | AD8: 45 | AE8: 6 | AF8: Ec | AG8: 35,40 | AI8: 50 | AJ8: 6 | AK8: Ib | AL8: 40 | AM8: 55 | AN8: 4 | AO8: Ec,Ob | AP8: 276 cr | AQ8: 62 | AR8: 18 | AS8: Ec,Ob | AT8: 55
B9: Programación | F9: Introducción a la Mecánica | J9: Mecánica y Ondas | N9: Termodinámica | R9: Bases de Datos | V9: Estructuras de Datos y Algoritmos | Z9: Artificial Intelligence | AD9: Almacenamiento y Procesamiento Masivo de Datos | AI9: Inteligencia Artificial Aplicada | AM9: Proyecto de Título 1 | AQ9: Proyecto de Título 2
A10: Curso 4 | B10: 4 | C10: 1 | D10: - | E10: - | F10: 11 | G10: 5 | H10: ='[2]Malla base'!H10 -> Ea | I10: 4 | J10: 17 | K10: 5 | L10: ='[2]Malla base'!L10 -> Ia | M10: 1 | N10: 23 | O10: 6 | P10: - | Q10: 9,16 | R10: 29 | S10: 6 | V10: 35 | W10: 6 | X10: Ic | Y10: 26,28 | Z10: 41 | AA10: 6 | AD10: 46 | AE10: 6 | AF10: Ec | AG10: 35 | AI10: 51 | AJ10: 6 | AK10: Ib | AL10: 33,40 | AM10: 56 | AN10: 6
B11: Bases para el Estudio de Ingeniería | F11: Biología de los Microorganismos | J11: Fundamentos de Economía | N11: Estática | R11: Concentración Tecnológica | V11: Web Technologies | Z11: Concentración Tecnológica | AD11: Introducción a la Ingeniería de Software | AI11: Sistemas Embebidos | AM11: Electivo Especialidad
A12: Curso 5 | B12: 5 | C12: 3 | E12: - | N12: 24 | O12: 3 | Q12: 7 | V12: 36 | W12: 6 | Z12: 42 | AA12: 6 | AB12: Ib(Ea) | AC12: 150 cr | AI12: 52 | AJ12: 6 | AM12: 57 | AN12: 6
B13: Taller de Proyectos de Ingeniería | N13: Ética | V13: Concentración Tecnológica | Z13: Pensamiento de Diseño Aplicado a Ingeniería | AI13: Electivo Especialidad | AM13: Electivo Especialidad
A14: Curso 6 | B14: 6 | C14: 3 | D14: - | E14: - | F14: 12 | G14: 3 | H14: - | I14: 6 | J14: 18 | K14: 3 | L14: - | M14: 12 | N14: 25 | O14: 4 | P14: - | Q14: - | R14: 30 | S14: 3 | T14: - | U14: 24 | AD14: 47 | AE14: 3 | AF14: - | AG14: - | AM14: 58 | AN14: 2 | AO14: ='[2]Malla base'!AO14 -> Ec,Ia | AP14: 270 cr
B15: Teología I | F15: Teología II | J15: Teología III | N15: Minor | R15: Filosofía de las Ciencias | AD15: Optativo Arte y Literatura/Historia y Pensamiento Contemporáneo | AM15: Seminario Ética Profesional
A16: Curso 7 | B16: 7 | C16: 3 | D16: - | E16: - | F16: 13 | G16: 3 | H16: - | I16: - | J16: 19 | K16: 4 | L16: - | M16: - | R16: 31 | S16: 4 | T16: - | U16: -
B17: Antropología Filosófica | F17: Optativo Arte y Literatura/Historia y Pensamiento Contemporáneo | J17: Minor | R17: Minor
X18: 37 | Y18: 12 | Z18: ='[2]Malla base'!Z18 -> Ic(Ea) | AA18: 170 cr | AO18: 59 | AP18: 12 | AQ18: ='[2]Malla base'!AQ18 -> Ic(Eb, Ob) | AR18: 282 cr
E19: * | F19: APR | X19: Pre-Professional Practice | AO19: Professional Practice
E20: Inglés ALTE 3
B22: # | C22: SCT | D22: HT | E22: Req.
B23: Nombre Curso

Sheet ICA Malla
B2: Año 1 | J2: Año 2 | R2: Año 3 | Z2: Año 4 | AI2: Año 5 | AQ2: Año 6
B3: 1 | F3: 2 | J3: 1 | N3: 2 | R3: 1 | V3: 2 | Z3: 1 | AD3: 2 | AI3: 1 | AM3: 2 | AQ3: 1
A4: Curso 1 | B4: 1 | C4: 10 | D4: - | E4: - | F4: 8 | G4: 6 | H4: - | I4: 1,4,3 | J4: 14 | K4: 6 | L4: - | M4: 3,8,9 | N4: 20 | O4: 6 | P4: - | Q4: 15 | R4: 26 | S4: 6 | U4: 3,15 | V4: 32 | W4: 6 | Y4: 14,26 | Z4: 38 | AA4: 6 | AB4: Ia | AC4: 26,33 | AD4: 43 | AE4: 9 | AF4: Ec | AG4: 35,38,39 | AI4: 48 | AJ4: 6 | AK4: Ec | AL4: 46 | AM4: 53 | AN4: 6 | AO4: Ic(Ob) | AP4: 52 | AQ4: 60 | AR4: 6 | AS4: Ob | AT4: 50,54
B5: Álgebra e Introducción al Cálculo | F5: Álgebra Lineal | J5: Ecuaciones Diferenciales | N5: Probabilidades y Estadística | R5: Metodos Numéricos | V5: Transferencia de Masa | Z5: Balances de Materia y Energía | AD5: Diseño y Optimización de Procesos Industriales | AI5: Gestión Residuos Sólidos y Remediación de Suelos | AM5: Wastewater Treatment | AQ5: Gestión Ambiental y Producción Limpia
A6: Curso 2 | B6: 2 | C6: 5 | D6: ='Malla base'!D6 -> Ea | E6: - | F6: 9 | G6: 6 | H6: - | I6: 1,4 | J6: 15 | K6: 6 | L6: - | M6: 3,9 | N6: 21 | O6: 6 | P6: ='Malla base'!P6 -> Eb | Q6: 15,16 | R6: 27 | S6: 6 | U6: 22 | V6: 33 | W6: 6 | Y6: 26,27 | Z6: 39 | AA6: 6 | AC6: 26,33 | AD6: 44 | AE6: 6 | AF6: Ib | AG6: 38,39 | AI6: 49 | AJ6: 6 | AK6: Ic(Ob) | AL6: 43 | AM6: 54 | AN6: 6 | AP6: 51 | AQ6: 61 | AR6: 6
B7: Fundamentos de Química | F7: Cálculo I | J7: Cálculo II | N7: Electricidad y Magnetismo | R7: Termotecnia | V7: Transferencia de Calor | Z7: Máquinas de Transformación Física y Química | AD7: Cinética y Diseño de Reactores Químicos | AI7: Air Quality and Environmental Pollution | AM7: Economía Ambiental y de los Recursos Naturales | AQ7: Electivo Especialidad
A8: Curso 3 | B8: 3 | C8: 5 | D8: - | E8: - | F8: 10 | G8: 6 | I8: 1 | J8: 16 | K8: 6 | L8: ='Malla base'!L8 -> Eb | M8: 10 | N8: 22 | O8: 5 | P8: ='Malla base'!P8 -> Eb | Q8: 2,15,16 | R8: 28 | S8: 6 | T8: Ec | U8: 11,22 | V8: 34 | W8: 6 | X8: Ic(Ea) | Y8: 14,23 | Z8: 40 | AA8: 6 | AC8: 34 | AD8: 45 | AE8: 6 | AG8: 20,40 | AI8: 50 | AJ8: 6 | AK8: Oa | AL8: 46 | AM8: 55 | AN8: 4 | AO8: Ec,Ob | AP8: 276 cr | AQ8: 62 | AR8: 18 | AS8: Ec,Ob | AT8: 55
B9: Programación | F9: Introducción a la Mecánica | J9: Mecánica y Ondas | N9: Termodinámica | R9: Microbiología Industrial y Ambiental | V9: Fluid Mechanics | Z9: Hidraúlica | AD9: Hidrología | AI9: Legislación y Evaluación de Impacto Ambiental | AM9: Proyecto de Título 1 | AQ9: Proyecto de Título 2
A10: Curso 4 | B10: 4 | C10: 1 | D10: - | E10: - | F10: 11 | G10: 5 | H10: ='Malla base'!H10 -> Ea | I10: 4 | J10: 17 | K10: 5 | L10: ='Malla base'!L10 -> Ia | M10: 1 | N10: 23 | O10: 6 | P10: - | Q10: 9,16 | R10: 29 | S10: 6 | V10: 35 | W10: 6 | X10: Ec | Y10: 28 | Z10: 41 | AA10: 6 | AD10: 46 | AE10: 6 | AF10: Ib | AG10: 28,38 | AI10: 51 | AJ10: 6 | AK10: Ec,Ob | AL10: 43,44 | AM10: 56 | AN10: 6
B11: Bases para el Estudio de Ingeniería | F11: Biología de los Microorganismos | J11: Fundamentos de Economía | N11: Estática | R11: Concentración Tecnológica | V11: Ecología, Medio Ambiente y Energía | Z11: Concentración Tecnológica | AD11: Ingeniería de Bioprocesos Ambientales | AI11: Evaluación de Proyectos de Ingeniería Ambiental | AM11: Electivo Especialidad
A12: Curso 5 | B12: 5 | C12: 3 | E12: - | N12: 24 | O12: 3 | Q12: 7 | V12: 36 | W12: 6 | Z12: 42 | AA12: 6 | AB12: ='Malla base'!AB12 -> Ib(Ea) | AC12: 150 cr | AI12: 52 | AJ12: 6 | AL12: 45 | AM12: 57 | AN12: 6
B13: Taller de Proyectos de Ingeniería | N13: Ética | V13: Concentración Tecnológica | Z13: Pensamiento de Diseño Aplicado a Ingeniería | AI13: Obras Civiles Sanitarias | AM13: Electivo Especialidad
A14: Curso 6 | B14: 6 | C14: 3 | D14: - | E14: - | F14: 12 | G14: 3 | H14: - | I14: 6 | J14: 18 | K14: 3 | L14: - | M14: 12 | N14: 25 | O14: 4 | P14: - | Q14: - | R14: 30 | S14: 3 | T14: - | U14: 24 | AD14: 47 | AE14: 3 | AF14: - | AG14: - | AM14: 58 | AN14: 2 | AO14: ='Malla base'!AO14 -> Ec,Ia | AP14: 270 cr
B15: Teología I | F15: Teología II | J15: Teología III | N15: Minor | R15: Filosofía de las Ciencias | AD15: Optativo Arte y Literatura/Historia y Pensamiento Contemporáneo | AM15: Seminario Ética Profesional
A16: Curso 7 | B16: 7 | C16: 3 | D16: - | E16: - | F16: 13 | G16: 3 | H16: - | I16: - | J16: 19 | K16: 4 | L16: - | M16: - | R16: 31 | S16: 4 | T16: - | U16: -
B17: Antropología Filosófica | F17: Optativo Arte y Literatura/Historia y Pensamiento Contemporáneo | J17: Minor | R17: Minor
X18: 37 | Y18: 12 | Z18: ='Malla base'!Z18 -> Ic(Ea) | AA18: 170 cr | AO18: 60 | AP18: 12 | AQ18: ='Malla base'!AQ18 -> Ic(Eb, Ob) | AR18: 282 cr
E19: * | F19: APR | X19: Pre-Professional Practice | AO19: Professional Practice
E20: Inglés ALTE 3
B22: # | C22: SCT | D22: HT | E22: Req.
B23: Nombre Curso
B25: Año 1 | J25: Año 2 | R25: Año 3 | Z25: Año 4 | AI25: Año 5 | AQ25: Año 6
B26: =C4+C6+C8+C10+C12+C14+C16+G4+G6+G8+G10+G14+G16 -> 59 | J26: =K4+K6+K8+K10+K14+K16+O4+O6+O8+O10+O12+O14 -> 60 | R26: =S4+S6+S8+S10+S14+S16+W4+W6+W8+W10+W12+Y18 -> 73 | Z26: =AA4+AA6+AA8+AA10+AA12+AA14+AE4+AE6+AE8+AE10+AE14 -> 60 | AI26: =AJ4+AJ6+AJ8+AJ10+AJ12+AN4+AN6+AN8+AN10+AN12+AN14+AP18 -> 72 | AQ26: =AR4+AR6+AR8 -> 30
